Workbook
Name ExtMarks: 'External Marks'!$B$18:$E$418
Name ExtMarksRHS: 'External Marks'!$I$18:$M$51
Name GSheetAB: 'Green Sheet'!$CA$1
Name SpecialGrade: 'White Sheet'!$CA$1:$CA$114

Sheet White Sheet
CB1: EMSHEET
CA2: Absent | CB2: WD_KACCM_B [F]
E3: Instituid Teicneolaiochta Phortlairge | F3: Instituid Teicneolaiochta Phortlairge | G3: Instituid Teicneolaiochta Phortlairge | H3: Instituid Teicneolaiochta Phortlairge | I3: Instituid Teicneolaiochta Phortlairge | J3: Instituid Teicneolaiochta Phortlairge | K3: PLEASE NOTE: Assessment Marks are sensitive personal data and therefore covered by GDPR rules. They should be stored safely and securely until handed over for the compilation of marks, while the corrected assessment material should be moved to a designated Exam Base Room. | L3: PLEASE NOTE: Assessment Marks are sensitive personal data and therefore covered by GDPR rules. They should be stored safely and securely until handed over for the compilation of marks, while the corrected assessment material should be moved to a designated Exam Base Room. | M3: PLEASE NOTE: Assessment Marks are sensitive personal data and therefore covered by GDPR rules. They should be stored safely and securely until handed over for the compilation of marks, while the corrected assessment material should be moved to a designated Exam Base Room. | CA3: Deferred | CB3: Functional Programming (PROG-0094)
E4: Waterford Institute of Technology | F4: Waterford Institute of Technology | G4: Waterford Institute of Technology | H4: Waterford Institute of Technology | I4: Waterford Institute of Technology | J4: Waterford Institute of Technology | K4: PLEASE NOTE: Assessment Marks are sensitive personal data and therefore covered by GDPR rules. They should be stored safely and securely until handed over for the compilation of marks, while the corrected assessment material should be moved to a designated Exam Base Room. | L4: PLEASE NOTE: Assessment Marks are sensitive personal data and therefore covered by GDPR rules. They should be stored safely and securely until handed over for the compilation of marks, while the corrected assessment material should be moved to a designated Exam Base Room. | M4: PLEASE NOTE: Assessment Marks are sensitive personal data and therefore covered by GDPR rules. They should be stored safely and securely until handed over for the compilation of marks, while the corrected assessment material should be moved to a designated Exam Base Room. | CA4: Exempt | CB4: SS
E5: May 2026 Examination Session | F5: May 2026 Examination Session | G5: May 2026 Examination Session | H5: May 2026 Examination Session | I5: May 2026 Examination Session | J5: May 2026 Examination Session | K5: PLEASE NOTE: Assessment Marks are sensitive personal data and therefore covered by GDPR rules. They should be stored safely and securely until handed over for the compilation of marks, while the corrected assessment material should be moved to a designated Exam Base Room. | L5: PLEASE NOTE: Assessment Marks are sensitive personal data and therefore covered by GDPR rules. They should be stored safely and securely until handed over for the compilation of marks, while the corrected assessment material should be moved to a designated Exam Base Room. | M5: PLEASE NOTE: Assessment Marks are sensitive personal data and therefore covered by GDPR rules. They should be stored safely and securely until handed over for the compilation of marks, while the corrected assessment material should be moved to a designated Exam Base Room. | CA5: Fail
K6: PLEASE NOTE: Assessment Marks are sensitive personal data and therefore covered by GDPR rules. They should be stored safely and securely until handed over for the compilation of marks, while the corrected assessment material should be moved to a designated Exam Base Room. | L6: PLEASE NOTE: Assessment Marks are sensitive personal data and therefore covered by GDPR rules. They should be stored safely and securely until handed over for the compilation of marks, while the corrected assessment material should be moved to a designated Exam Base Room. | M6: PLEASE NOTE: Assessment Marks are sensitive personal data and therefore covered by GDPR rules. They should be stored safely and securely until handed over for the compilation of marks, while the corrected assessment material should be moved to a designated Exam Base Room. | CA6: Failed Component
E7: SUBJECT MARK SHEET | F7: SUBJECT MARK SHEET | G7: SUBJECT MARK SHEET | H7: SUBJECT MARK SHEET | I7: SUBJECT MARK SHEET | J7: SUBJECT MARK SHEET | K7: PLEASE NOTE: Assessment Marks are sensitive personal data and therefore covered by GDPR rules. They should be stored safely and securely until handed over for the compilation of marks, while the corrected assessment material should be moved to a designated Exam Base Room. | L7: PLEASE NOTE: Assessment Marks are sensitive personal data and therefore covered by GDPR rules. They should be stored safely and securely until handed over for the compilation of marks, while the corrected assessment material should be moved to a designated Exam Base Room. | M7: PLEASE NOTE: Assessment Marks are sensitive personal data and therefore covered by GDPR rules. They should be stored safely and securely until handed over for the compilation of marks, while the corrected assessment material should be moved to a designated Exam Base Room. | CA7: Pass
L8: Section Reference | CA8: Placement Deferred
C9: School of Science and Computing | D9: School of Science and Computing | L9: 30486 - L01 | CA9: Recommended
L10: 00000 - | CA10: Not Recommended
C11: Bachelor of Science (Honours) in App Computing (Common Entry) Year 4 | D11: Bachelor of Science (Honours) in App Computing (Common Entry) Year 4 | E11: Bachelor of Science (Honours) in App Computing (Common Entry) Year 4 | F11: Bachelor of Science (Honours) in App Computing (Common Entry) Year 4 | G11: Bachelor of Science (Honours) in App Computing (Common Entry) Year 4 | H11: Bachelor of Science (Honours) in App Computing (Common Entry) Year 4 | I11: Bachelor of Science (Honours) in App Computing (Common Entry) Year 4 | J11: Bachelor of Science (Honours) in App Computing (Common Entry) Year 4 | CA11: Not Recorded
CA12: Zero
C13: Module: | D13: Functional Programming (PROG-0094) | E13: Functional Programming (PROG-0094) | F13: Functional Programming (PROG-0094) | G13: Functional Programming (PROG-0094) | H13: Functional Programming (PROG-0094) | I13: Functional Programming (PROG-0094) | L13: Total Students: 34 | M13: Total Students: 34 | CA13: Satisfactory Progress
CA14: Unsatisfactory Progress
D15: Component % Breakdown | E15: 50 | F15: 5 | G15: 5 | H15: 40 | I15: 0 | J15: 0 | K15: 0 | L15: =IF(SUM(E15:K15) <> 0, IF(SUM(E15:K15) <> 100, " Total % not equal to 100!", ""), "") | CA15: 1
CA16: 2
C17: Student No | D17: Student Name | E17: Written | F17: Lab-T-1 | G17: Lab_T-2 | H17: ProgAss | I17: Item 4 | J17: Item 5 | K17: Item 6 | L17: TOTAL | M17: Special Grade | CA17: 3
C18: W20102008 | D18: Barron, Davin | E18: =IF('Green Sheet'!Q18="AB", "AB", IF(ISERR('Green Sheet'!P18), 0, 'Green Sheet'!P18)) -> 0 | F18: 80 | G18: 100 | H18: 81 | L18: =(IF(E18="AB", 0, E18)*(E15/100)) + (IF(F18="AB", 0, F18)*(F15/100)) +(IF(G18="AB", 0, G18)*(G15/100)) + (IF(H18="AB", 0, H18)*(H15/100)) + (IF(I18="AB", 0, I18)*(I15/100)) + (IF(J18="AB", 0, J18)*(J15/100)) + (IF(K18="AB", 0, K18)*(K15/100)) -> 41.4 | O18: 373534 | P18: 30486 | Q18: N | CA18: 4
C19: W20102006 | D19: Bennett, Finn | E19: =IF('Green Sheet'!Q19="AB", "AB", IF(ISERR('Green Sheet'!P19), 0, 'Green Sheet'!P19)) -> 0 | F19: 84 | G19: 95 | H19: 54.8 | L19: =(IF(E19="AB", 0, E19)*(E15/100)) + (IF(F19="AB", 0, F19)*(F15/100)) +(IF(G19="AB", 0, G19)*(G15/100)) + (IF(H19="AB", 0, H19)*(H15/100)) + (IF(I19="AB", 0, I19)*(I15/100)) + (IF(J19="AB", 0, J19)*(J15/100)) + (IF(K19="AB", 0, K19)*(K15/100)) -> 30.87 | O19: 373523 | P19: 30486 | Q19: N | CA19: 5
C20: W20102486 | D20: Bonner, Evan | E20: =IF('Green Sheet'!Q20="AB", "AB", IF(ISERR('Green Sheet'!P20), 0, 'Green Sheet'!P20)) -> 0 | F20: 72 | G20: 0 | H20: 0 | L20: =(IF(E20="AB", 0, E20)*(E15/100)) + (IF(F20="AB", 0, F20)*(F15/100)) +(IF(G20="AB", 0, G20)*(G15/100)) + (IF(H20="AB", 0, H20)*(H15/100)) + (IF(I20="AB", 0, I20)*(I15/100)) + (IF(J20="AB", 0, J20)*(J15/100)) + (IF(K20="AB", 0, K20)*(K15/100)) -> 3.6 | O20: 376646 | P20: 30486 | Q20: N | CA20: 6
C21: W20101992 | D21: Browne, Jessica | E21: =IF('Green Sheet'!Q21="AB", "AB", IF(ISERR('Green Sheet'!P21), 0, 'Green Sheet'!P21)) -> 0 | F21: 72 | G21: 35 | H21: 61 | L21: =(IF(E21="AB", 0, E21)*(E15/100)) + (IF(F21="AB", 0, F21)*(F15/100)) +(IF(G21="AB", 0, G21)*(G15/100)) + (IF(H21="AB", 0, H21)*(H15/100)) + (IF(I21="AB", 0, I21)*(I15/100)) + (IF(J21="AB", 0, J21)*(J15/100)) + (IF(K21="AB", 0, K21)*(K15/100)) -> 29.75 | O21: 373349 | P21: 30486 | Q21: N | CA21: 7
C22: W20101456 | D22: Casey, Jeremiah | E22: =IF('Green Sheet'!Q22="AB", "AB", IF(ISERR('Green Sheet'!P22), 0, 'Green Sheet'!P22)) -> 0 | F22: 46.86 | G22: 10 | H22: 0 | L22: =(IF(E22="AB", 0, E22)*(E15/100)) + (IF(F22="AB", 0, F22)*(F15/100)) +(IF(G22="AB", 0, G22)*(G15/100)) + (IF(H22="AB", 0, H22)*(H15/100)) + (IF(I22="AB", 0, I22)*(I15/100)) + (IF(J22="AB", 0, J22)*(J15/100)) + (IF(K22="AB", 0, K22)*(K15/100)) -> 2.843 | O22: 319664 | P22: 30486 | Q22: N | CA22: 8
C23: W20102506 | D23: Clarke, Emma | E23: =IF('Green Sheet'!Q23="AB", "AB", IF(ISERR('Green Sheet'!P23), 0, 'Green Sheet'!P23)) -> 0 | F23: 100 | G23: 55 | H23: 56.5 | L23: =(IF(E23="AB", 0, E23)*(E15/100)) + (IF(F23="AB", 0, F23)*(F15/100)) +(IF(G23="AB", 0, G23)*(G15/100)) + (IF(H23="AB", 0, H23)*(H15/100)) + (IF(I23="AB", 0, I23)*(I15/100)) + (IF(J23="AB", 0, J23)*(J15/100)) + (IF(K23="AB", 0, K23)*(K15/100)) -> 30.35 | O23: 376763 | P23: 30486 | Q23: N | CA23: 9
C24: W20102299 | D24: Cleary, Sinead | E24: =IF('Green Sheet'!Q24="AB", "AB", IF(ISERR('Green Sheet'!P24), 0, 'Green Sheet'!P24)) -> 0 | F24: 100 | G24: 100 | H24: 67.5 | L24: =(IF(E24="AB", 0, E24)*(E15/100)) + (IF(F24="AB", 0, F24)*(F15/100)) +(IF(G24="AB", 0, G24)*(G15/100)) + (IF(H24="AB", 0, H24)*(H15/100)) + (IF(I24="AB", 0, I24)*(I15/100)) + (IF(J24="AB", 0, J24)*(J15/100)) + (IF(K24="AB", 0, K24)*(K15/100)) -> 37 | O24: 375606 | P24: 30486 | Q24: N | CA24: 10
C25: W20101841 | D25: Condon, Tommy | E25: =IF('Green Sheet'!Q25="AB", "AB", IF(ISERR('Green Sheet'!P25), 0, 'Green Sheet'!P25)) -> 0 | F25: 100 | G25: 95 | H25: 76 | L25: =(IF(E25="AB", 0, E25)*(E15/100)) + (IF(F25="AB", 0, F25)*(F15/100)) +(IF(G25="AB", 0, G25)*(G15/100)) + (IF(H25="AB", 0, H25)*(H15/100)) + (IF(I25="AB", 0, I25)*(I15/100)) + (IF(J25="AB", 0, J25)*(J15/100)) + (IF(K25="AB", 0, K25)*(K15/100)) -> 40.15 | O25: 372156 | P25: 30486 | Q25: N | CA25: 11
C26: W20101954 | D26: Costigan-Dooley, Adam | E26: =IF('Green Sheet'!Q26="AB", "AB", IF(ISERR('Green Sheet'!P26), 0, 'Green Sheet'!P26)) -> 0 | F26: 88 | G26: 100 | H26: 6.3 | L26: =(IF(E26="AB", 0, E26)*(E15/100)) + (IF(F26="AB", 0, F26)*(F15/100)) +(IF(G26="AB", 0, G26)*(G15/100)) + (IF(H26="AB", 0, H26)*(H15/100)) + (IF(I26="AB", 0, I26)*(I15/100)) + (IF(J26="AB", 0, J26)*(J15/100)) + (IF(K26="AB", 0, K26)*(K15/100)) -> 11.92 | O26: 373036 | P26: 30486 | Q26: N | CA26: 12
C27: W20102180 | D27: Cullen, Calum | E27: =IF('Green Sheet'!Q27="AB", "AB", IF(ISERR('Green Sheet'!P27), 0, 'Green Sheet'!P27)) -> 0 | F27: 88 | G27: 100 | H27: 56.5 | L27: =(IF(E27="AB", 0, E27)*(E15/100)) + (IF(F27="AB", 0, F27)*(F15/100)) +(IF(G27="AB", 0, G27)*(G15/100)) + (IF(H27="AB", 0, H27)*(H15/100)) + (IF(I27="AB", 0, I27)*(I15/100)) + (IF(J27="AB", 0, J27)*(J15/100)) + (IF(K27="AB", 0, K27)*(K15/100)) -> 32 | O27: 380037 | P27: 30486 | Q27: N | CA27: 13
C28: W20102969 | D28: Falkowski, Dominik | E28: =IF('Green Sheet'!Q28="AB", "AB", IF(ISERR('Green Sheet'!P28), 0, 'Green Sheet'!P28)) -> 0 | F28: 95 | G28: 100 | H28: 52.85 | L28: =(IF(E28="AB", 0, E28)*(E15/100)) + (IF(F28="AB", 0, F28)*(F15/100)) +(IF(G28="AB", 0, G28)*(G15/100)) + (IF(H28="AB", 0, H28)*(H15/100)) + (IF(I28="AB", 0, I28)*(I15/100)) + (IF(J28="AB", 0, J28)*(J15/100)) + (IF(K28="AB", 0, K28)*(K15/100)) -> 30.89 | O28: 373034 | P28: 30486 | Q28: N | CA28: 14
C29: W20102629 | D29: Fitzgerald, Paul | E29: =IF('Green Sheet'!Q29="AB", "AB", IF(ISERR('Green Sheet'!P29), 0, 'Green Sheet'!P29)) -> 0 | F29: 96 | G29: 100 | L29: =(IF(E29="AB", 0, E29)*(E15/100)) + (IF(F29="AB", 0, F29)*(F15/100)) +(IF(G29="AB", 0, G29)*(G15/100)) + (IF(H29="AB", 0, H29)*(H15/100)) + (IF(I29="AB", 0, I29)*(I15/100)) + (IF(J29="AB", 0, J29)*(J15/100)) + (IF(K29="AB", 0, K29)*(K15/100)) -> 9.8 | O29: 377637 | P29: 30486 | Q29: N | CA29: 15
C30: W20102427 | D30: Halley, Jeff | E30: =IF('Green Sheet'!Q30="AB", "AB", IF(ISERR('Green Sheet'!P30), 0, 'Green Sheet'!P30)) -> 0 | F30: 68 | G30: 100 | H30: 73 | L30: =(IF(E30="AB", 0, E30)*(E15/100)) + (IF(F30="AB", 0, F30)*(F15/100)) +(IF(G30="AB", 0, G30)*(G15/100)) + (IF(H30="AB", 0, H30)*(H15/100)) + (IF(I30="AB", 0, I30)*(I15/100)) + (IF(J30="AB", 0, J30)*(J15/100)) + (IF(K30="AB", 0, K30)*(K15/100)) -> 37.6 | O30: 376328 | P30: 30486 | Q30: N | CA30: 16
C31: W20102466 | D31: Heeney, Graham | E31: =IF('Green Sheet'!Q31="AB", "AB", IF(ISERR('Green Sheet'!P31), 0, 'Green Sheet'!P31)) -> 0 | F31: 80 | G31: 100 | H31: 62.5 | L31: =(IF(E31="AB", 0, E31)*(E15/100)) + (IF(F31="AB", 0, F31)*(F15/100)) +(IF(G31="AB", 0, G31)*(G15/100)) + (IF(H31="AB", 0, H31)*(H15/100)) + (IF(I31="AB", 0, I31)*(I15/100)) + (IF(J31="AB", 0, J31)*(J15/100)) + (IF(K31="AB", 0, K31)*(K15/100)) -> 34 | O31: 382152 | P31: 30486 | Q31: N | CA31: 17
C32: W20102236 | D32: Kapusniak, Igor | E32: =IF('Green Sheet'!Q32="AB", "AB", IF(ISERR('Green Sheet'!P32), 0, 'Green Sheet'!P32)) -> 0 | F32: 100 | G32: 100 | H32: 80.5 | L32: =(IF(E32="AB", 0, E32)*(E15/100)) + (IF(F32="AB", 0, F32)*(F15/100)) +(IF(G32="AB", 0, G32)*(G15/100)) + (IF(H32="AB", 0, H32)*(H15/100)) + (IF(I32="AB", 0, I32)*(I15/100)) + (IF(J32="AB", 0, J32)*(J15/100)) + (IF(K32="AB", 0, K32)*(K15/100)) -> 42.2 | O32: 375229 | P32: 30486 | Q32: N | CA32: 18
C33: W20098883 | D33: Keevers, Brona | E33: =IF('Green Sheet'!Q33="AB", "AB", IF(ISERR('Green Sheet'!P33), 0, 'Green Sheet'!P33)) -> 0 | F33: 0 | G33: 0 | H33: 77.5 | L33: =(IF(E33="AB", 0, E33)*(E15/100)) + (IF(F33="AB", 0, F33)*(F15/100)) +(IF(G33="AB", 0, G33)*(G15/100)) + (IF(H33="AB", 0, H33)*(H15/100)) + (IF(I33="AB", 0, I33)*(I15/100)) + (IF(J33="AB", 0, J33)*(J15/100)) + (IF(K33="AB", 0, K33)*(K15/100)) -> 31 | O33: 365952 | P33: 30486 | Q33: N | CA33: 19
C34: W20101947 | D34: Kelleher, Christopher | E34: =IF('Green Sheet'!Q34="AB", "AB", IF(ISERR('Green Sheet'!P34), 0, 'Green Sheet'!P34)) -> 0 | F34: 100 | G34: 100 | H34: 48.5 | L34: =(IF(E34="AB", 0, E34)*(E15/100)) + (IF(F34="AB", 0, F34)*(F15/100)) +(IF(G34="AB", 0, G34)*(G15/100)) + (IF(H34="AB", 0, H34)*(H15/100)) + (IF(I34="AB", 0, I34)*(I15/100)) + (IF(J34="AB", 0, J34)*(J15/100)) + (IF(K34="AB", 0, K34)*(K15/100)) -> 29.4 | O34: 372979 | P34: 30486 | Q34: N | CA34: 20
C35: W20102588 | D35: Kenny, Adam | E35: =IF('Green Sheet'!Q35="AB", "AB", IF(ISERR('Green Sheet'!P35), 0, 'Green Sheet'!P35)) -> 0 | F35: 100 | G35: 0 | H35: 48.5 | L35: =(IF(E35="AB", 0, E35)*(E15/100)) + (IF(F35="AB", 0, F35)*(F15/100)) +(IF(G35="AB", 0, G35)*(G15/100)) + (IF(H35="AB", 0, H35)*(H15/100)) + (IF(I35="AB", 0, I35)*(I15/100)) + (IF(J35="AB", 0, J35)*(J15/100)) + (IF(K35="AB", 0, K35)*(K15/100)) -> 24.4 | O35: 377340 | P35: 30486 | Q35: N | CA35: 21
C36: W20103125 | D36: Lipceanu, George | E36: =IF('Green Sheet'!Q36="AB", "AB", IF(ISERR('Green Sheet'!P36), 0, 'Green Sheet'!P36)) -> 0 | F36: 100 | G36: 100 | L36: =(IF(E36="AB", 0, E36)*(E15/100)) + (IF(F36="AB", 0, F36)*(F15/100)) +(IF(G36="AB", 0, G36)*(G15/100)) + (IF(H36="AB", 0, H36)*(H15/100)) + (IF(I36="AB", 0, I36)*(I15/100)) + (IF(J36="AB", 0, J36)*(J15/100)) + (IF(K36="AB", 0, K36)*(K15/100)) -> 10 | O36: 375171 | P36: 30486 | Q36: N | CA36: 22
C37: W20102256 | D37: Lyster Cummins, Samuel | E37: =IF('Green Sheet'!Q37="AB", "AB", IF(ISERR('Green Sheet'!P37), 0, 'Green Sheet'!P37)) -> 0 | F37: 100 | G37: 0 | H37: 82.5 | L37: =(IF(E37="AB", 0, E37)*(E15/100)) + (IF(F37="AB", 0, F37)*(F15/100)) +(IF(G37="AB", 0, G37)*(G15/100)) + (IF(H37="AB", 0, H37)*(H15/100)) + (IF(I37="AB", 0, I37)*(I15/100)) + (IF(J37="AB", 0, J37)*(J15/100)) + (IF(K37="AB", 0, K37)*(K15/100)) -> 38 | O37: 381865 | P37: 30486 | Q37: N | CA37: 23
C38: W20102482 | D38: Malczuk, Krzysztof | E38: =IF('Green Sheet'!Q38="AB", "AB", IF(ISERR('Green Sheet'!P38), 0, 'Green Sheet'!P38)) -> 0 | F38: 100 | G38: 20 | H38: 81 | L38: =(IF(E38="AB", 0, E38)*(E15/100)) + (IF(F38="AB", 0, F38)*(F15/100)) +(IF(G38="AB", 0, G38)*(G15/100)) + (IF(H38="AB", 0, H38)*(H15/100)) + (IF(I38="AB", 0, I38)*(I15/100)) + (IF(J38="AB", 0, J38)*(J15/100)) + (IF(K38="AB", 0, K38)*(K15/100)) -> 38.4 | O38: 338978 | P38: 30486 | Q38: N | CA38: 24
C39: W20098764 | D39: Mary, Matteo | E39: =IF('Green Sheet'!Q39="AB", "AB", IF(ISERR('Green Sheet'!P39), 0, 'Green Sheet'!P39)) -> 0 | F39: 100 | G39: 100 | H39: 62.5 | L39: =(IF(E39="AB", 0, E39)*(E15/100)) + (IF(F39="AB", 0, F39)*(F15/100)) +(IF(G39="AB", 0, G39)*(G15/100)) + (IF(H39="AB", 0, H39)*(H15/100)) + (IF(I39="AB", 0, I39)*(I15/100)) + (IF(J39="AB", 0, J39)*(J15/100)) + (IF(K39="AB", 0, K39)*(K15/100)) -> 35 | O39: 369708 | P39: 30486 | Q39: N | CA39: 25
C40: W20103121 | D40: Mc Grath, Stephen | E40: =IF('Green Sheet'!Q40="AB", "AB", IF(ISERR('Green Sheet'!P40), 0, 'Green Sheet'!P40)) -> 0 | F40: 100 | G40: 100 | L40: =(IF(E40="AB", 0, E40)*(E15/100)) + (IF(F40="AB", 0, F40)*(F15/100)) +(IF(G40="AB", 0, G40)*(G15/100)) + (IF(H40="AB", 0, H40)*(H15/100)) + (IF(I40="AB", 0, I40)*(I15/100)) + (IF(J40="AB", 0, J40)*(J15/100)) + (IF(K40="AB", 0, K40)*(K15/100)) -> 10 | O40: 375136 | P40: 30486 | Q40: N | CA40: 26
...

Sheet Green Sheet
CA1: AB
C3: Instituid Teicneolaiochta Phortlairge | D3: Instituid Teicneolaiochta Phortlairge | E3: Instituid Teicneolaiochta Phortlairge | F3: Instituid Teicneolaiochta Phortlairge | G3: Instituid Teicneolaiochta Phortlairge | H3: Instituid Teicneolaiochta Phortlairge | I3: Instituid Teicneolaiochta Phortlairge | J3: Instituid Teicneolaiochta Phortlairge | K3: Instituid Teicneolaiochta Phortlairge | L3: Instituid Teicneolaiochta Phortlairge | M3: Instituid Teicneolaiochta Phortlairge | N3: Instituid Teicneolaiochta Phortlairge | O3: Instituid Teicneolaiochta Phortlairge | P3: Instituid Teicneolaiochta Phortlairge
C4: Waterford Institute of Technology | D4: Waterford Institute of Technology | E4: Waterford Institute of Technology | F4: Waterford Institute of Technology | G4: Waterford Institute of Technology | H4: Waterford Institute of Technology | I4: Waterford Institute of Technology | J4: Waterford Institute of Technology | K4: Waterford Institute of Technology | L4: Waterford Institute of Technology | M4: Waterford Institute of Technology | N4: Waterford Institute of Technology | O4: Waterford Institute of Technology | P4: Waterford Institute of Technology
C5: May 2026 Examination Session | D5: May 2026 Examination Session | E5: May 2026 Examination Session | F5: May 2026 Examination Session | G5: May 2026 Examination Session | H5: May 2026 Examination Session | I5: May 2026 Examination Session | J5: May 2026 Examination Session | K5: May 2026 Examination Session | L5: May 2026 Examination Session | M5: May 2026 Examination Session | N5: May 2026 Examination Session | O5: May 2026 Examination Session | P5: May 2026 Examination Session
C7: COMPONENT MARK SHEET | D7: COMPONENT MARK SHEET | E7: COMPONENT MARK SHEET | F7: COMPONENT MARK SHEET | G7: COMPONENT MARK SHEET | H7: COMPONENT MARK SHEET | I7: COMPONENT MARK SHEET | J7: COMPONENT MARK SHEET | K7: COMPONENT MARK SHEET | L7: COMPONENT MARK SHEET | M7: COMPONENT MARK SHEET | N7: COMPONENT MARK SHEET | O7: COMPONENT MARK SHEET | P7: COMPONENT MARK SHEET
C9: School of Science and Computing | D9: School of Science and Computing | N9: Total Students: 34 | O9: Total Students: 34 | P9: Total Students: 34
C11: Bachelor of Science (Honours) in App Computing (Common Entry) Year 4 | D11: Bachelor of Science (Honours) in App Computing (Common Entry) Year 4 | E11: Bachelor of Science (Honours) in App Computing (Common Entry) Year 4 | F11: Bachelor of Science (Honours) in App Computing (Common Entry) Year 4 | G11: Bachelor of Science (Honours) in App Computing (Common Entry) Year 4 | H11: Bachelor of Science (Honours) in App Computing (Common Entry) Year 4 | I11: Bachelor of Science (Honours) in App Computing (Common Entry) Year 4 | J11: Bachelor of Science (Honours) in App Computing (Common Entry) Year 4 | K11: Bachelor of Science (Honours) in App Computing (Common Entry) Year 4 | N11: Maximum | O11: Maximum | P11: 100
C13: Module: | D13: Functional Programming (PROG-0094) | E13: Functional Programming (PROG-0094) | F13: Functional Programming (PROG-0094) | G13: Functional Programming (PROG-0094) | H13: Functional Programming (PROG-0094) | I13: Functional Programming (PROG-0094) | J13: Functional Programming (PROG-0094) | N13: Mark out of | P13: 0 | Q13: questions
C15: Compulsory Questions (mark with an X) | AE15: =IF(E15="X", 1, 0) -> 0 | AF15: =IF(F15="X", 1, 0) -> 0 | AG15: =IF(G15="X", 1, 0) -> 0 | AH15: =IF(H15="X", 1, 0) -> 0 | AI15: =IF(I15="X", 1, 0) -> 0 | AJ15: =IF(J15="X", 1, 0) -> 0 | AK15: =IF(K15="X", 1, 0) -> 0 | AL15: =IF(L15="X", 1, 0) -> 0 | ... AN15: =IF(N15="X", 1, 0) -> 0 | AO15: =SUM(AE15:AN15) -> 0
C17: Student No | D17: Student Name | E17: Q1 | F17: Q2 | G17: Q3 | H17: Q4 | I17: Q5 | J17: Q6 | K17: Q7 | L17: Q8 | M17: Q9 | N17: Q10 | O17: TOTAL | P17: TOTAL % | Q17: AB?
C18: W20102008 | D18: Barron, Davin | O18: =CB18 -> #REF! | P18: =(O18*100)/P11 -> #REF! | CB18: {=SUM(LARGE(IF(ISNUMBER(E18:N18),E18:N18*$AE$15:$AN$15,0),ROW(INDIRECT(CONCATENATE("1:"&$P$13)))))+IF(($P$13-$AO$15)>0,SUM(LARGE(IF(ISNUMBER(E18:N18),IF($AE$15:$AN$15=0,E18:N18,0),0),ROW(INDIRECT(CONCATENATE("1:"&$P$13-$AO$15))))),0)} -> #REF! | CC18: #REF! | CD18: #REF! | CE18: #REF! | CF18: #REF! | CG18: #REF! | CH18: #REF! | CI18: #REF! | CJ18: #REF! | CK18: #REF! | CL18: #REF!
C19: W20102006 | D19: Bennett, Finn | O19: =CB19 -> #REF! | P19: =(O19*100)/P11 -> #REF! | CB19: {=SUM(LARGE(IF(ISNUMBER(E19:N19),E19:N19*$AE$15:$AN$15,0),ROW(INDIRECT(CONCATENATE("1:"&$P$13)))))+IF(($P$13-$AO$15)>0,SUM(LARGE(IF(ISNUMBER(E19:N19),IF($AE$15:$AN$15=0,E19:N19,0),0),ROW(INDIRECT(CONCATENATE("1:"&$P$13-$AO$15))))),0)} -> #REF! | CC19: #REF! | CD19: #REF! | CE19: #REF! | CF19: #REF! | CG19: #REF! | CH19: #REF! | CI19: #REF! | CJ19: #REF! | CK19: #REF! | CL19: #REF!
C20: W20102486 | D20: Bonner, Evan | O20: =CB20 -> #REF! | P20: =(O20*100)/P11 -> #REF! | CB20: {=SUM(LARGE(IF(ISNUMBER(E20:N20),E20:N20*$AE$15:$AN$15,0),ROW(INDIRECT(CONCATENATE("1:"&$P$13)))))+IF(($P$13-$AO$15)>0,SUM(LARGE(IF(ISNUMBER(E20:N20),IF($AE$15:$AN$15=0,E20:N20,0),0),ROW(INDIRECT(CONCATENATE("1:"&$P$13-$AO$15))))),0)} -> #REF! | CC20: #REF! | CD20: #REF! | CE20: #REF! | CF20: #REF! | CG20: #REF! | CH20: #REF! | CI20: #REF! | CJ20: #REF! | CK20: #REF! | CL20: #REF!
C21: W20101992 | D21: Browne, Jessica | O21: =CB21 -> #REF! | P21: =(O21*100)/P11 -> #REF! | CB21: {=SUM(LARGE(IF(ISNUMBER(E21:N21),E21:N21*$AE$15:$AN$15,0),ROW(INDIRECT(CONCATENATE("1:"&$P$13)))))+IF(($P$13-$AO$15)>0,SUM(LARGE(IF(ISNUMBER(E21:N21),IF($AE$15:$AN$15=0,E21:N21,0),0),ROW(INDIRECT(CONCATENATE("1:"&$P$13-$AO$15))))),0)} -> #REF! | CC21: #REF! | CD21: #REF! | CE21: #REF! | CF21: #REF! | CG21: #REF! | CH21: #REF! | CI21: #REF! | CJ21: #REF! | CK21: #REF! | CL21: #REF!
C22: W20101456 | D22: Casey, Jeremiah | O22: =CB22 -> #REF! | P22: =(O22*100)/P11 -> #REF! | CB22: {=SUM(LARGE(IF(ISNUMBER(E22:N22),E22:N22*$AE$15:$AN$15,0),ROW(INDIRECT(CONCATENATE("1:"&$P$13)))))+IF(($P$13-$AO$15)>0,SUM(LARGE(IF(ISNUMBER(E22:N22),IF($AE$15:$AN$15=0,E22:N22,0),0),ROW(INDIRECT(CONCATENATE("1:"&$P$13-$AO$15))))),0)} -> #REF! | CC22: #REF! | CD22: #REF! | CE22: #REF! | CF22: #REF! | CG22: #REF! | CH22: #REF! | CI22: #REF! | CJ22: #REF! | CK22: #REF! | CL22: #REF!
C23: W20102506 | D23: Clarke, Emma | O23: =CB23 -> #REF! | P23: =(O23*100)/P11 -> #REF! | CB23: {=SUM(LARGE(IF(ISNUMBER(E23:N23),E23:N23*$AE$15:$AN$15,0),ROW(INDIRECT(CONCATENATE("1:"&$P$13)))))+IF(($P$13-$AO$15)>0,SUM(LARGE(IF(ISNUMBER(E23:N23),IF($AE$15:$AN$15=0,E23:N23,0),0),ROW(INDIRECT(CONCATENATE("1:"&$P$13-$AO$15))))),0)} -> #REF! | CC23: #REF! | CD23: #REF! | CE23: #REF! | CF23: #REF! | CG23: #REF! | CH23: #REF! | CI23: #REF! | CJ23: #REF! | CK23: #REF! | CL23: #REF!
C24: W20102299 | D24: Cleary, Sinead | O24: =CB24 -> #REF! | P24: =(O24*100)/P11 -> #REF! | CB24: {=SUM(LARGE(IF(ISNUMBER(E24:N24),E24:N24*$AE$15:$AN$15,0),ROW(INDIRECT(CONCATENATE("1:"&$P$13)))))+IF(($P$13-$AO$15)>0,SUM(LARGE(IF(ISNUMBER(E24:N24),IF($AE$15:$AN$15=0,E24:N24,0),0),ROW(INDIRECT(CONCATENATE("1:"&$P$13-$AO$15))))),0)} -> #REF! | CC24: #REF! | CD24: #REF! | CE24: #REF! | CF24: #REF! | CG24: #REF! | CH24: #REF! | CI24: #REF! | CJ24: #REF! | CK24: #REF! | CL24: #REF!
C25: W20101841 | D25: Condon, Tommy | O25: =CB25 -> #REF! | P25: =(O25*100)/P11 -> #REF! | CB25: {=SUM(LARGE(IF(ISNUMBER(E25:N25),E25:N25*$AE$15:$AN$15,0),ROW(INDIRECT(CONCATENATE("1:"&$P$13)))))+IF(($P$13-$AO$15)>0,SUM(LARGE(IF(ISNUMBER(E25:N25),IF($AE$15:$AN$15=0,E25:N25,0),0),ROW(INDIRECT(CONCATENATE("1:"&$P$13-$AO$15))))),0)} -> #REF! | CC25: #REF! | CD25: #REF! | CE25: #REF! | CF25: #REF! | CG25: #REF! | CH25: #REF! | CI25: #REF! | CJ25: #REF! | CK25: #REF! | CL25: #REF!
C26: W20101954 | D26: Costigan-Dooley, Adam | O26: =CB26 -> #REF! | P26: =(O26*100)/P11 -> #REF! | CB26: {=SUM(LARGE(IF(ISNUMBER(E26:N26),E26:N26*$AE$15:$AN$15,0),ROW(INDIRECT(CONCATENATE("1:"&$P$13)))))+IF(($P$13-$AO$15)>0,SUM(LARGE(IF(ISNUMBER(E26:N26),IF($AE$15:$AN$15=0,E26:N26,0),0),ROW(INDIRECT(CONCATENATE("1:"&$P$13-$AO$15))))),0)} -> #REF! | CC26: #REF! | CD26: #REF! | CE26: #REF! | CF26: #REF! | CG26: #REF! | CH26: #REF! | CI26: #REF! | CJ26: #REF! | CK26: #REF! | CL26: #REF!
C27: W20102180 | D27: Cullen, Calum | O27: =CB27 -> #REF! | P27: =(O27*100)/P11 -> #REF! | CB27: {=SUM(LARGE(IF(ISNUMBER(E27:N27),E27:N27*$AE$15:$AN$15,0),ROW(INDIRECT(CONCATENATE("1:"&$P$13)))))+IF(($P$13-$AO$15)>0,SUM(LARGE(IF(ISNUMBER(E27:N27),IF($AE$15:$AN$15=0,E27:N27,0),0),ROW(INDIRECT(CONCATENATE("1:"&$P$13-$AO$15))))),0)} -> #REF! | CC27: #REF! | CD27: #REF! | CE27: #REF! | CF27: #REF! | CG27: #REF! | CH27: #REF! | CI27: #REF! | CJ27: #REF! | CK27: #REF! | CL27: #REF!
C28: W20102969 | D28: Falkowski, Dominik | O28: =CB28 -> #REF! | P28: =(O28*100)/P11 -> #REF! | CB28: {=SUM(LARGE(IF(ISNUMBER(E28:N28),E28:N28*$AE$15:$AN$15,0),ROW(INDIRECT(CONCATENATE("1:"&$P$13)))))+IF(($P$13-$AO$15)>0,SUM(LARGE(IF(ISNUMBER(E28:N28),IF($AE$15:$AN$15=0,E28:N28,0),0),ROW(INDIRECT(CONCATENATE("1:"&$P$13-$AO$15))))),0)} -> #REF! | CC28: #REF! | CD28: #REF! | CE28: #REF! | CF28: #REF! | CG28: #REF! | CH28: #REF! | CI28: #REF! | CJ28: #REF! | CK28: #REF! | CL28: #REF!
C29: W20102629 | D29: Fitzgerald, Paul | O29: =CB29 -> #REF! | P29: =(O29*100)/P11 -> #REF! | CB29: {=SUM(LARGE(IF(ISNUMBER(E29:N29),E29:N29*$AE$15:$AN$15,0),ROW(INDIRECT(CONCATENATE("1:"&$P$13)))))+IF(($P$13-$AO$15)>0,SUM(LARGE(IF(ISNUMBER(E29:N29),IF($AE$15:$AN$15=0,E29:N29,0),0),ROW(INDIRECT(CONCATENATE("1:"&$P$13-$AO$15))))),0)} -> #REF! | CC29: #REF! | CD29: #REF! | CE29: #REF! | CF29: #REF! | CG29: #REF! | CH29: #REF! | CI29: #REF! | CJ29: #REF! | CK29: #REF! | CL29: #REF!
C30: W20102427 | D30: Halley, Jeff | O30: =CB30 -> #REF! | P30: =(O30*100)/P11 -> #REF! | CB30: {=SUM(LARGE(IF(ISNUMBER(E30:N30),E30:N30*$AE$15:$AN$15,0),ROW(INDIRECT(CONCATENATE("1:"&$P$13)))))+IF(($P$13-$AO$15)>0,SUM(LARGE(IF(ISNUMBER(E30:N30),IF($AE$15:$AN$15=0,E30:N30,0),0),ROW(INDIRECT(CONCATENATE("1:"&$P$13-$AO$15))))),0)} -> #REF! | CC30: #REF! | CD30: #REF! | CE30: #REF! | CF30: #REF! | CG30: #REF! | CH30: #REF! | CI30: #REF! | CJ30: #REF! | CK30: #REF! | CL30: #REF!
C31: W20102466 | D31: Heeney, Graham | O31: =CB31 -> #REF! | P31: =(O31*100)/P11 -> #REF! | CB31: {=SUM(LARGE(IF(ISNUMBER(E31:N31),E31:N31*$AE$15:$AN$15,0),ROW(INDIRECT(CONCATENATE("1:"&$P$13)))))+IF(($P$13-$AO$15)>0,SUM(LARGE(IF(ISNUMBER(E31:N31),IF($AE$15:$AN$15=0,E31:N31,0),0),ROW(INDIRECT(CONCATENATE("1:"&$P$13-$AO$15))))),0)} -> #REF! | CC31: #REF! | CD31: #REF! | CE31: #REF! | CF31: #REF! | CG31: #REF! | CH31: #REF! | CI31: #REF! | CJ31: #REF! | CK31: #REF! | CL31: #REF!
C32: W20102236 | D32: Kapusniak, Igor | O32: =CB32 -> #REF! | P32: =(O32*100)/P11 -> #REF! | CB32: {=SUM(LARGE(IF(ISNUMBER(E32:N32),E32:N32*$AE$15:$AN$15,0),ROW(INDIRECT(CONCATENATE("1:"&$P$13)))))+IF(($P$13-$AO$15)>0,SUM(LARGE(IF(ISNUMBER(E32:N32),IF($AE$15:$AN$15=0,E32:N32,0),0),ROW(INDIRECT(CONCATENATE("1:"&$P$13-$AO$15))))),0)} -> #REF! | CC32: #REF! | CD32: #REF! | CE32: #REF! | CF32: #REF! | CG32: #REF! | CH32: #REF! | CI32: #REF! | CJ32: #REF! | CK32: #REF! | CL32: #REF!
C33: W20098883 | D33: Keevers, Brona | O33: =CB33 -> #REF! | P33: =(O33*100)/P11 -> #REF! | CB33: {=SUM(LARGE(IF(ISNUMBER(E33:N33),E33:N33*$AE$15:$AN$15,0),ROW(INDIRECT(CONCATENATE("1:"&$P$13)))))+IF(($P$13-$AO$15)>0,SUM(LARGE(IF(ISNUMBER(E33:N33),IF($AE$15:$AN$15=0,E33:N33,0),0),ROW(INDIRECT(CONCATENATE("1:"&$P$13-$AO$15))))),0)} -> #REF! | CC33: #REF! | CD33: #REF! | CE33: #REF! | CF33: #REF! | CG33: #REF! | CH33: #REF! | CI33: #REF! | CJ33: #REF! | CK33: #REF! | CL33: #REF!
C34: W20101947 | D34: Kelleher, Christopher | O34: =CB34 -> #REF! | P34: =(O34*100)/P11 -> #REF! | CB34: {=SUM(LARGE(IF(ISNUMBER(E34:N34),E34:N34*$AE$15:$AN$15,0),ROW(INDIRECT(CONCATENATE("1:"&$P$13)))))+IF(($P$13-$AO$15)>0,SUM(LARGE(IF(ISNUMBER(E34:N34),IF($AE$15:$AN$15=0,E34:N34,0),0),ROW(INDIRECT(CONCATENATE("1:"&$P$13-$AO$15))))),0)} -> #REF! | CC34: #REF! | CD34: #REF! | CE34: #REF! | CF34: #REF! | CG34: #REF! | CH34: #REF! | CI34: #REF! | CJ34: #REF! | CK34: #REF! | CL34: #REF!
C35: W20102588 | D35: Kenny, Adam | O35: =CB35 -> #REF! | P35: =(O35*100)/P11 -> #REF! | CB35: {=SUM(LARGE(IF(ISNUMBER(E35:N35),E35:N35*$AE$15:$AN$15,0),ROW(INDIRECT(CONCATENATE("1:"&$P$13)))))+IF(($P$13-$AO$15)>0,SUM(LARGE(IF(ISNUMBER(E35:N35),IF($AE$15:$AN$15=0,E35:N35,0),0),ROW(INDIRECT(CONCATENATE("1:"&$P$13-$AO$15))))),0)} -> #REF! | CC35: #REF! | CD35: #REF! | CE35: #REF! | CF35: #REF! | CG35: #REF! | CH35: #REF! | CI35: #REF! | CJ35: #REF! | CK35: #REF! | CL35: #REF!
C36: W20103125 | D36: Lipceanu, George | O36: =CB36 -> #REF! | P36: =(O36*100)/P11 -> #REF! | CB36: {=SUM(LARGE(IF(ISNUMBER(E36:N36),E36:N36*$AE$15:$AN$15,0),ROW(INDIRECT(CONCATENATE("1:"&$P$13)))))+IF(($P$13-$AO$15)>0,SUM(LARGE(IF(ISNUMBER(E36:N36),IF($AE$15:$AN$15=0,E36:N36,0),0),ROW(INDIRECT(CONCATENATE("1:"&$P$13-$AO$15))))),0)} -> #REF! | CC36: #REF! | CD36: #REF! | CE36: #REF! | CF36: #REF! | CG36: #REF! | CH36: #REF! | CI36: #REF! | CJ36: #REF! | CK36: #REF! | CL36: #REF!
C37: W20102256 | D37: Lyster Cummins, Samuel | O37: =CB37 -> #REF! | P37: =(O37*100)/P11 -> #REF! | CB37: {=SUM(LARGE(IF(ISNUMBER(E37:N37),E37:N37*$AE$15:$AN$15,0),ROW(INDIRECT(CONCATENATE("1:"&$P$13)))))+IF(($P$13-$AO$15)>0,SUM(LARGE(IF(ISNUMBER(E37:N37),IF($AE$15:$AN$15=0,E37:N37,0),0),ROW(INDIRECT(CONCATENATE("1:"&$P$13-$AO$15))))),0)} -> #REF! | CC37: #REF! | CD37: #REF! | CE37: #REF! | CF37: #REF! | CG37: #REF! | CH37: #REF! | CI37: #REF! | CJ37: #REF! | CK37: #REF! | CL37: #REF!
C38: W20102482 | D38: Malczuk, Krzysztof | O38: =CB38 -> #REF! | P38: =(O38*100)/P11 -> #REF! | CB38: {=SUM(LARGE(IF(ISNUMBER(E38:N38),E38:N38*$AE$15:$AN$15,0),ROW(INDIRECT(CONCATENATE("1:"&$P$13)))))+IF(($P$13-$AO$15)>0,SUM(LARGE(IF(ISNUMBER(E38:N38),IF($AE$15:$AN$15=0,E38:N38,0),0),ROW(INDIRECT(CONCATENATE("1:"&$P$13-$AO$15))))),0)} -> #REF! | CC38: #REF! | CD38: #REF! | CE38: #REF! | CF38: #REF! | CG38: #REF! | CH38: #REF! | CI38: #REF! | CJ38: #REF! | CK38: #REF! | CL38: #REF!
C39: W20098764 | D39: Mary, Matteo | O39: =CB39 -> #REF! | P39: =(O39*100)/P11 -> #REF! | CB39: {=SUM(LARGE(IF(ISNUMBER(E39:N39),E39:N39*$AE$15:$AN$15,0),ROW(INDIRECT(CONCATENATE("1:"&$P$13)))))+IF(($P$13-$AO$15)>0,SUM(LARGE(IF(ISNUMBER(E39:N39),IF($AE$15:$AN$15=0,E39:N39,0),0),ROW(INDIRECT(CONCATENATE("1:"&$P$13-$AO$15))))),0)} -> #REF! | CC39: #REF! | CD39: #REF! | CE39: #REF! | CF39: #REF! | CG39: #REF! | CH39: #REF! | CI39: #REF! | CJ39: #REF! | CK39: #REF! | CL39: #REF!
C40: W20103121 | D40: Mc Grath, Stephen | O40: =CB40 -> #REF! | P40: =(O40*100)/P11 -> #REF! | CB40: {=SUM(LARGE(IF(ISNUMBER(E40:N40),E40:N40*$AE$15:$AN$15,0),ROW(INDIRECT(CONCATENATE("1:"&$P$13)))))+IF(($P$13-$AO$15)>0,SUM(LARGE(IF(ISNUMBER(E40:N40),IF($AE$15:$AN$15=0,E40:N40,0),0),ROW(INDIRECT(CONCATENATE("1:"&$P$13-$AO$15))))),0)} -> #REF! | CC40: #REF! | CD40: #REF! | CE40: #REF! | CF40: #REF! | CG40: #REF! | CH40: #REF! | CI40: #REF! | CJ40: #REF! | CK40: #REF! | CL40: #REF!
C41: W20098619 | D41: Mikalauskas, Radvydas | O41: =CB41 -> #REF! | P41: =(O41*100)/P11 -> #REF! | CB41: {=SUM(LARGE(IF(ISNUMBER(E41:N41),E41:N41*$AE$15:$AN$15,0),ROW(INDIRECT(CONCATENATE("1:"&$P$13)))))+IF(($P$13-$AO$15)>0,SUM(LARGE(IF(ISNUMBER(E41:N41),IF($AE$15:$AN$15=0,E41:N41,0),0),ROW(INDIRECT(CONCATENATE("1:"&$P$13-$AO$15))))),0)} -> #REF! | CC41: #REF! | CD41: #REF! | CE41: #REF! | CF41: #REF! | CG41: #REF! | CH41: #REF! | CI41: #REF! | CJ41: #REF! | CK41: #REF! | CL41: #REF!
C42: W20103495 | D42: Neary, Ava | O42: =CB42 -> #REF! | P42: =(O42*100)/P11 -> #REF! | CB42: {=SUM(LARGE(IF(ISNUMBER(E42:N42),E42:N42*$AE$15:$AN$15,0),ROW(INDIRECT(CONCATENATE("1:"&$P$13)))))+IF(($P$13-$AO$15)>0,SUM(LARGE(IF(ISNUMBER(E42:N42),IF($AE$15:$AN$15=0,E42:N42,0),0),ROW(INDIRECT(CONCATENATE("1:"&$P$13-$AO$15))))),0)} -> #REF! | CC42: #REF! | CD42: #REF! | CE42: #REF! | CF42: #REF! | CG42: #REF! | CH42: #REF! | CI42: #REF! | CJ42: #REF! | CK42: #REF! | CL42: #REF!
C43: W20098583 | D43: O Connor, Jay | O43: =CB43 -> #REF! | P43: =(O43*100)/P11 -> #REF! | CB43: {=SUM(LARGE(IF(ISNUMBER(E43:N43),E43:N43*$AE$15:$AN$15,0),ROW(INDIRECT(CONCATENATE("1:"&$P$13)))))+IF(($P$13-$AO$15)>0,SUM(LARGE(IF(ISNUMBER(E43:N43),IF($AE$15:$AN$15=0,E43:N43,0),0),ROW(INDIRECT(CONCATENATE("1:"&$P$13-$AO$15))))),0)} -> #REF! | CC43: #REF! | CD43: #REF! | CE43: #REF! | CF43: #REF! | CG43: #REF! | CH43: #REF! | CI43: #REF! | CJ43: #REF! | CK43: #REF! | CL43: #REF!
C44: W20098626 | D44: O Mahony, John | O44: =CB44 -> #REF! | P44: =(O44*100)/P11 -> #REF! | CB44: {=SUM(LARGE(IF(ISNUMBER(E44:N44),E44:N44*$AE$15:$AN$15,0),ROW(INDIRECT(CONCATENATE("1:"&$P$13)))))+IF(($P$13-$AO$15)>0,SUM(LARGE(IF(ISNUMBER(E44:N44),IF($AE$15:$AN$15=0,E44:N44,0),0),ROW(INDIRECT(CONCATENATE("1:"&$P$13-$AO$15))))),0)} -> #REF! | CC44: #REF! | CD44: #REF! | CE44: #REF! | CF44: #REF! | CG44: #REF! | CH44: #REF! | CI44: #REF! | CJ44: #REF! | CK44: #REF! | CL44: #REF!
C45: W20101948 | D45: O'Brien, Daniel | O45: =CB45 -> #REF! | P45: =(O45*100)/P11 -> #REF! | CB45: {=SUM(LARGE(IF(ISNUMBER(E45:N45),E45:N45*$AE$15:$AN$15,0),ROW(INDIRECT(CONCATENATE("1:"&$P$13)))))+IF(($P$13-$AO$15)>0,SUM(LARGE(IF(ISNUMBER(E45:N45),IF($AE$15:$AN$15=0,E45:N45,0),0),ROW(INDIRECT(CONCATENATE("1:"&$P$13-$AO$15))))),0)} -> #REF! | CC45: #REF! | CD45: #REF! | CE45: #REF! | CF45: #REF! | CG45: #REF! | CH45: #REF! | CI45: #REF! | CJ45: #REF! | CK45: #REF! | CL45: #REF!
C46: W20102592 | D46: Power, Shane | O46: =CB46 -> #REF! | P46: =(O46*100)/P11 -> #REF! | CB46: {=SUM(LARGE(IF(ISNUMBER(E46:N46),E46:N46*$AE$15:$AN$15,0),ROW(INDIRECT(CONCATENATE("1:"&$P$13)))))+IF(($P$13-$AO$15)>0,SUM(LARGE(IF(ISNUMBER(E46:N46),IF($AE$15:$AN$15=0,E46:N46,0),0),ROW(INDIRECT(CONCATENATE("1:"&$P$13-$AO$15))))),0)} -> #REF! | CC46: #REF! | CD46: #REF! | CE46: #REF! | CF46: #REF! | CG46: #REF! | CH46: #REF! | CI46: #REF! | CJ46: #REF! | CK46: #REF! | CL46: #REF!
C47: W20101977 | D47: Reilly, Fionn | O47: =CB47 -> #REF! | P47: =(O47*100)/P11 -> #REF! | CB47: {=SUM(LARGE(IF(ISNUMBER(E47:N47),E47:N47*$AE$15:$AN$15,0),ROW(INDIRECT(CONCATENATE("1:"&$P$13)))))+IF(($P$13-$AO$15)>0,SUM(LARGE(IF(ISNUMBER(E47:N47),IF($AE$15:$AN$15=0,E47:N47,0),0),ROW(INDIRECT(CONCATENATE("1:"&$P$13-$AO$15))))),0)} -> #REF! | CC47: #REF! | CD47: #REF! | CE47: #REF! | CF47: #REF! | CG47: #REF! | CH47: #REF! | CI47: #REF! | CJ47: #REF! | CK47: #REF! | CL47: #REF!
...

Sheet External Marks
C3: Step 1: | D3: Paste your results in the red box below - must have student number in first column! | I3: Step 3: | J3: Select all cells in the orange column and press Ctrl+C to COPY
I5: Step 4: | J5: Place the cursor in the top cell of the green column, right-click and on the menu click on Paste Special and then choose the first 'Paste Values' option - the '123 with blank clipboard' one
C8: Step 2: | D8: Check the number of marks on both sides matches up
I9: Step 5: | J9: Now with the green column still selected, press Ctrl+H to open Find and Replace. Tick 'Match entire cell contents'. Put 0 in the 'Find What' and nothing in the 'Replace With'. Now click 'Replace All'
I13: Step 6: | J13: Now copy the complete green column and paste this into the desired column in the White or Green worksheet
C17: Student No | D17: Student Name | E17: ="#Marks: " & COUNT(E18:E418) -> #Marks: 0 | I17: Student No | J17: Student Name | K17: ="#Marks: " & COUNTIF(K18:K418, ">0") -> #Marks: 0 | M17: ="#Marks: " & COUNT(M18:M418) -> #Marks: 0
B18: =IF(LEFT(C18, 2)="20", "W" & C18, C18) | F18: =IF(C18= " ", "", IFERROR(VLOOKUP(B18, ExtMarksRHS, 4, FALSE), "X")) | I18: W20102008 | J18: Barron, Davin | K18: =IFERROR(VLOOKUP(I18, ExtMarks, 4, FALSE), 0) -> 0
B19: =IF(LEFT(C19, 2)="20", "W" & C19, C19) | F19: =IF(C19= " ", "", IFERROR(VLOOKUP(B19, ExtMarksRHS, 4, FALSE), "X")) | I19: W20102006 | J19: Bennett, Finn | K19: =IFERROR(VLOOKUP(I19, ExtMarks, 4, FALSE), 0) -> 0
B20: =IF(LEFT(C20, 2)="20", "W" & C20, C20) | F20: =IF(C20= " ", "", IFERROR(VLOOKUP(B20, ExtMarksRHS, 4, FALSE), "X")) | I20: W20102486 | J20: Bonner, Evan | K20: =IFERROR(VLOOKUP(I20, ExtMarks, 4, FALSE), 0) -> 0
B21: =IF(LEFT(C21, 2)="20", "W" & C21, C21) | F21: =IF(C21= " ", "", IFERROR(VLOOKUP(B21, ExtMarksRHS, 4, FALSE), "X")) | I21: W20101992 | J21: Browne, Jessica | K21: =IFERROR(VLOOKUP(I21, ExtMarks, 4, FALSE), 0) -> 0
B22: =IF(LEFT(C22, 2)="20", "W" & C22, C22) | F22: =IF(C22= " ", "", IFERROR(VLOOKUP(B22, ExtMarksRHS, 4, FALSE), "X")) | I22: W20101456 | J22: Casey, Jeremiah | K22: =IFERROR(VLOOKUP(I22, ExtMarks, 4, FALSE), 0) -> 0
B23: =IF(LEFT(C23, 2)="20", "W" & C23, C23) | F23: =IF(C23= " ", "", IFERROR(VLOOKUP(B23, ExtMarksRHS, 4, FALSE), "X")) | I23: W20102506 | J23: Clarke, Emma | K23: =IFERROR(VLOOKUP(I23, ExtMarks, 4, FALSE), 0) -> 0
B24: =IF(LEFT(C24, 2)="20", "W" & C24, C24) | F24: =IF(C24= " ", "", IFERROR(VLOOKUP(B24, ExtMarksRHS, 4, FALSE), "X")) | I24: W20102299 | J24: Cleary, Sinead | K24: =IFERROR(VLOOKUP(I24, ExtMarks, 4, FALSE), 0) -> 0
B25: =IF(LEFT(C25, 2)="20", "W" & C25, C25) | F25: =IF(C25= " ", "", IFERROR(VLOOKUP(B25, ExtMarksRHS, 4, FALSE), "X")) | I25: W20101841 | J25: Condon, Tommy | K25: =IFERROR(VLOOKUP(I25, ExtMarks, 4, FALSE), 0) -> 0
B26: =IF(LEFT(C26, 2)="20", "W" & C26, C26) | F26: =IF(C26= " ", "", IFERROR(VLOOKUP(B26, ExtMarksRHS, 4, FALSE), "X")) | I26: W20101954 | J26: Costigan-Dooley, Adam | K26: =IFERROR(VLOOKUP(I26, ExtMarks, 4, FALSE), 0) -> 0
B27: =IF(LEFT(C27, 2)="20", "W" & C27, C27) | F27: =IF(C27= " ", "", IFERROR(VLOOKUP(B27, ExtMarksRHS, 4, FALSE), "X")) | I27: W20102180 | J27: Cullen, Calum | K27: =IFERROR(VLOOKUP(I27, ExtMarks, 4, FALSE), 0) -> 0
B28: =IF(LEFT(C28, 2)="20", "W" & C28, C28) | F28: =IF(C28= " ", "", IFERROR(VLOOKUP(B28, ExtMarksRHS, 4, FALSE), "X")) | I28: W20102969 | J28: Falkowski, Dominik | K28: =IFERROR(VLOOKUP(I28, ExtMarks, 4, FALSE), 0) -> 0
B29: =IF(LEFT(C29, 2)="20", "W" & C29, C29) | F29: =IF(C29= " ", "", IFERROR(VLOOKUP(B29, ExtMarksRHS, 4, FALSE), "X")) | I29: W20102629 | J29: Fitzgerald, Paul | K29: =IFERROR(VLOOKUP(I29, ExtMarks, 4, FALSE), 0) -> 0
... B51: =IF(LEFT(C51, 2)="20", "W" & C51, C51) | F51: =IF(C51= " ", "", IFERROR(VLOOKUP(B51, ExtMarksRHS, 4, FALSE), "X")) | I51: W20102420 | J51: Zaharia, Alan | K51: =IFERROR(VLOOKUP(I51, ExtMarks, 4, FALSE), 0) -> 0
B52: =IF(LEFT(C52, 2)="20", "W" & C52, C52) | F52: =IF(C52= " ", "", IFERROR(VLOOKUP(B52, ExtMarksRHS, 4, FALSE), "X"))
B53: =IF(LEFT(C53, 2)="20", "W" & C53, C53) | F53: =IF(C53= " ", "", IFERROR(VLOOKUP(B53, ExtMarksRHS, 4, FALSE), "X"))
B54: =IF(LEFT(C54, 2)="20", "W" & C54, C54) | F54: =IF(C54= " ", "", IFERROR(VLOOKUP(B54, ExtMarksRHS, 4, FALSE), "X"))
B55: =IF(LEFT(C55, 2)="20", "W" & C55, C55) | F55: =IF(C55= " ", "", IFERROR(VLOOKUP(B55, ExtMarksRHS, 4, FALSE), "X"))
B56: =IF(LEFT(C56, 2)="20", "W" & C56, C56) | F56: =IF(C56= " ", "", IFERROR(VLOOKUP(B56, ExtMarksRHS, 4, FALSE), "X"))
B57: =IF(LEFT(C57, 2)="20", "W" & C57, C57) | F57: =IF(C57= " ", "", IFERROR(VLOOKUP(B57, ExtMarksRHS, 4, FALSE), "X"))
B58: =IF(LEFT(C58, 2)="20", "W" & C58, C58) | F58: =IF(C58= " ", "", IFERROR(VLOOKUP(B58, ExtMarksRHS, 4, FALSE), "X"))
B59: =IF(LEFT(C59, 2)="20", "W" & C59, C59) | F59: =IF(C59= " ", "", IFERROR(VLOOKUP(B59, ExtMarksRHS, 4, FALSE), "X"))
B60: =IF(LEFT(C60, 2)="20", "W" & C60, C60) | F60: =IF(C60= " ", "", IFERROR(VLOOKUP(B60, ExtMarksRHS, 4, FALSE), "X"))
B61: =IF(LEFT(C61, 2)="20", "W" & C61, C61) | F61: =IF(C61= " ", "", IFERROR(VLOOKUP(B61, ExtMarksRHS, 4, FALSE), "X"))
B62: =IF(LEFT(C62, 2)="20", "W" & C62, C62) | F62: =IF(C62= " ", "", IFERROR(VLOOKUP(B62, ExtMarksRHS, 4, FALSE), "X"))
B63: =IF(LEFT(C63, 2)="20", "W" & C63, C63) | F63: =IF(C63= " ", "", IFERROR(VLOOKUP(B63, ExtMarksRHS, 4, FALSE), "X"))
... B418: =IF(LEFT(C418, 2)="20", "W" & C418, C418) | F418: =IF(C418= " ", "", IFERROR(VLOOKUP(B418, ExtMarksRHS, 4, FALSE), "X"))

Sheet Roughwork Sheet
C18: W20102008 | D18: Barron, Davin
C19: W20102006 | D19: Bennett, Finn
C20: W20102486 | D20: Bonner, Evan
C21: W20101992 | D21: Browne, Jessica
C22: W20101456 | D22: Casey, Jeremiah
C23: W20102506 | D23: Clarke, Emma
C24: W20102299 | D24: Cleary, Sinead
C25: W20101841 | D25: Condon, Tommy
C26: W20101954 | D26: Costigan-Dooley, Adam
C27: W20102180 | D27: Cullen, Calum
C28: W20102969 | D28: Falkowski, Dominik
C29: W20102629 | D29: Fitzgerald, Paul
... C58: --- Missing | D58: Student---
