Workbook

Sheet Export Summary
B3: This document was exported from Numbers. Each table was converted to an Excel worksheet. All other objects on each Numbers sheet were placed on separate worksheets. Please be aware that formula calculations may differ in Excel.
B7: Numbers Sheet Name | C7: Numbers Table Name | D7: Excel Worksheet Name
B9: master
C10: Master marks | D10: master - Master marks
B11: lab test 1
C12: lab test 1 (5%) | D12: lab test 1 - lab test 1 (5%)
B13: lab test 2
C14: lab test 2 (5 %) | D14: lab test 2 - lab test 2 (5 %)
B15: Phase 1 - Programming Assignment
C16: Formative Assessment (0%) | D16: Phase 1 - Programming Assignmen
B17: Programming Assignment 40%
C18: Programming Assignment 40% | D18: Programming Assignment 40% - Pr

Sheet master - Master marks
A1: Master marks
A6: Surname | B6: First name | F6: lab test 1 (5%) | G6: lab test 2 5% | H6: Prog assign 40% | I6: Total CA (%) | J6: Total CA (50) | K6: Written Paper (%) | L6: Written Paper (50) | M6: Final Total | N6: Repeat Requirements
F7: 100 | G7: 100 | H7: 100
A8: Dawid | B8: Beres | C8: 20098868@mail.wit.ie | F8: ='lab test 1 - lab test 1 (5%)'!I7 -> 100 | G8: ='lab test 2 - lab test 2 (5 %)'!H6 -> 0 | H8: ='Programming Assignment 40% - Pr'!AH8 -> 0 | I8: =F8*0.1+G8*0.1+H8*0.8 -> 10 | J8: =I8/2 -> 5 | L8: =K8/2 -> 0 | M8: =J8+L8 -> 5 | N8: Repeat Programming Assignment and FP
A9: Jan | B9: Biernacki | C9: 20098580@mail.wit.ie | F9: ='lab test 1 - lab test 1 (5%)'!I8 -> 100 | G9: ='lab test 2 - lab test 2 (5 %)'!H7 -> 2 | H9: ='Programming Assignment 40% - Pr'!AH9 -> 0 | I9: =F9*0.1+G9*0.1+H9*0.8 -> 10.2 | J9: =I9/2 -> 5.1 | K9: 41 | L9: =K9/2 -> 20.5 | M9: =J9+L9 -> 25.6
A10: Arthur | B10: Bilyk | C10: 20097938@mail.wit.ie | F10: ='lab test 1 - lab test 1 (5%)'!I9 -> 91 | G10: ='lab test 2 - lab test 2 (5 %)'!H8 -> 80 | H10: ='Programming Assignment 40% - Pr'!AH10 -> 0 | I10: =F10*0.1+G10*0.1+H10*0.8 -> 17.1 | J10: =I10/2 -> 8.55 | K10: 54 | L10: =K10/2 -> 27 | M10: =J10+L10 -> 35.55
A11: Adam | B11: Cahill | C11: 20097733@mail.wit.ie | F11: ='lab test 1 - lab test 1 (5%)'!I10 -> 92 | G11: ='lab test 2 - lab test 2 (5 %)'!H9 -> 0 | H11: ='Programming Assignment 40% - Pr'!AH11 -> 0 | I11: =F11*0.1+G11*0.1+H11*0.8 -> 9.2 | J11: =I11/2 -> 4.6 | K11: 38.5 | L11: =K11/2 -> 19.25 | M11: =J11+L11 -> 23.85
A12: Dylan | B12: Chai | C12: 20099297@mail.wit.ie | F12: ='lab test 1 - lab test 1 (5%)'!I11 -> 95.714286 | G12: ='lab test 2 - lab test 2 (5 %)'!H10 -> 0 | H12: ='Programming Assignment 40% - Pr'!AH12 -> 0 | I12: =F12*0.1+G12*0.1+H12*0.8 -> 9.5714286 | J12: =I12/2 -> 4.7857143 | K12: 62 | L12: =K12/2 -> 31 | M12: =J12+L12 -> 35.785714
A13: Rendijs | B13: Cielava | C13: 20098325@mail.wit.ie | F13: ='lab test 1 - lab test 1 (5%)'!I12 -> 100 | G13: ='lab test 2 - lab test 2 (5 %)'!H11 -> 0 | H13: ='Programming Assignment 40% - Pr'!AH13 -> 0 | I13: =F13*0.1+G13*0.1+H13*0.8 -> 10 | J13: =I13/2 -> 5 | K13: 45.5 | L13: =K13/2 -> 22.75 | M13: =J13+L13 -> 27.75
A14: Liam | B14: Doocey | C14: 20094146@mail.wit.ie | F14: ='lab test 1 - lab test 1 (5%)'!I13 -> 77.714286 | G14: ='lab test 2 - lab test 2 (5 %)'!H12 -> 0 | H14: ='Programming Assignment 40% - Pr'!AH14 -> 0 | I14: =F14*0.1+G14*0.1+H14*0.8 -> 7.7714286 | J14: =I14/2 -> 3.8857143 | K14: 47 | L14: =K14/2 -> 23.5 | M14: =J14+L14 -> 27.385714
A15: Dean | B15: Doyle | C15: 20096595@mail.wit.ie | F15: ='lab test 1 - lab test 1 (5%)'!I14 -> 0 | G15: ='lab test 2 - lab test 2 (5 %)'!H13 -> 0 | H15: ='Programming Assignment 40% - Pr'!AH15 -> 0 | I15: =F15*0.1+G15*0.1+H15*0.8 -> 0 | J15: =I15/2 -> 0 | K15: 38.5 | L15: =K15/2 -> 19.25 | M15: =J15+L15 -> 19.25
A16: Alex | B16: Fan | C16: 20077347@mail.wit.ie | F16: ='lab test 1 - lab test 1 (5%)'!I15 -> 100 | G16: ='lab test 2 - lab test 2 (5 %)'!H14 -> 0 | H16: ='Programming Assignment 40% - Pr'!AH16 -> 0 | I16: =F16*0.1+G16*0.1+H16*0.8 -> 10 | J16: =I16/2 -> 5 | L16: =K16/2 -> 0 | M16: =J16+L16 -> 5 | N16: Repeat CA and FP
A17: Thomas | B17: Farrell | C17: 20083540@mail.wit.ie | F17: ='lab test 1 - lab test 1 (5%)'!I16 -> 68 | G17: ='lab test 2 - lab test 2 (5 %)'!H15 -> 80 | H17: ='Programming Assignment 40% - Pr'!AH17 -> 0 | I17: =F17*0.1+G17*0.1+H17*0.8 -> 14.8 | J17: =I17/2 -> 7.4 | K17: 47.5 | L17: =K17/2 -> 23.75 | M17: =J17+L17 -> 31.15
A18: Jordan | B18: Flynn | C18: 20096714@mail.wit.ie | F18: ='lab test 1 - lab test 1 (5%)'!I17 -> 60 | G18: ='lab test 2 - lab test 2 (5 %)'!H16 -> 0 | H18: ='Programming Assignment 40% - Pr'!AH18 -> 0 | I18: =F18*0.1+G18*0.1+H18*0.8 -> 6 | J18: =I18/2 -> 3 | K18: 69 | L18: =K18/2 -> 34.5 | M18: =J18+L18 -> 37.5
A19: Liam | B19: Flynn | C19: 20098690@mail.wit.ie | F19: ='lab test 1 - lab test 1 (5%)'!I18 -> 100 | G19: ='lab test 2 - lab test 2 (5 %)'!H17 -> 0 | H19: ='Programming Assignment 40% - Pr'!AH19 -> 0 | I19: =F19*0.1+G19*0.1+H19*0.8 -> 10 | J19: =I19/2 -> 5 | K19: 72 | L19: =K19/2 -> 36 | M19: =J19+L19 -> 41
A20: Kyla | B20: Franks | C20: 20098155@mail.wit.ie | F20: ='lab test 1 - lab test 1 (5%)'!I19 -> 100 | G20: ='lab test 2 - lab test 2 (5 %)'!H18 -> 0 | H20: ='Programming Assignment 40% - Pr'!AH20 -> 0 | I20: =F20*0.1+G20*0.1+H20*0.8 -> 10 | J20: =I20/2 -> 5 | K20: 88 | L20: =K20/2 -> 44 | M20: =J20+L20 -> 49
A21: Gjorgi | B21: Gjorgiev | C21: 20098721@mail.wit.ie | F21: ='lab test 1 - lab test 1 (5%)'!I20 -> 95 | G21: ='lab test 2 - lab test 2 (5 %)'!H19 -> 0 | H21: ='Programming Assignment 40% - Pr'!AH21 -> 0 | I21: =F21*0.1+G21*0.1+H21*0.8 -> 9.5 | J21: =I21/2 -> 4.75 | K21: 38.5 | L21: =K21/2 -> 19.25 | M21: =J21+L21 -> 24 | N21: Brought to 35 - passed by compensation
A22: Killian | B22: Golds | C22: 20070585@mail.wit.ie | F22: ='lab test 1 - lab test 1 (5%)'!I21 -> 0 | G22: ='lab test 2 - lab test 2 (5 %)'!H20 -> 0 | H22: ='Programming Assignment 40% - Pr'!AH22 -> 0 | I22: =F22*0.1+G22*0.1+H22*0.8 -> 0 | J22: =I22/2 -> 0 | K22: 91.5 | L22: =K22/2 -> 45.75 | M22: =J22+L22 -> 45.75
A23: Evan | B23: Hearne | C23: 20097562@mail.wit.ie | F23: ='lab test 1 - lab test 1 (5%)'!I22 -> 96 | G23: ='lab test 2 - lab test 2 (5 %)'!H21 -> 0 | H23: ='Programming Assignment 40% - Pr'!AH23 -> 0 | I23: =F23*0.1+G23*0.1+H23*0.8 -> 9.6 | J23: =I23/2 -> 4.8 | K23: 66.5 | L23: =K23/2 -> 33.25 | M23: =J23+L23 -> 38.05
A24: Ciaran | B24: Hickey | C24: 20088959@mail.wit.ie | F24: ='lab test 1 - lab test 1 (5%)'!I23 -> 87.714286 | G24: ='lab test 2 - lab test 2 (5 %)'!H22 -> 0 | H24: ='Programming Assignment 40% - Pr'!AH24 -> 0 | I24: =F24*0.1+G24*0.1+H24*0.8 -> 8.7714286 | J24: =I24/2 -> 4.3857143 | K24: 35.5 | L24: =K24/2 -> 17.75 | M24: =J24+L24 -> 22.135714
A25: Mark | B25: Hogan | C25: 20098168@mail.wit.ie | F25: ='lab test 1 - lab test 1 (5%)'!I24 -> 100 | G25: ='lab test 2 - lab test 2 (5 %)'!H23 -> 0 | H25: ='Programming Assignment 40% - Pr'!AH25 -> 0 | I25: =F25*0.1+G25*0.1+H25*0.8 -> 10 | J25: =I25/2 -> 5 | K25: 61 | L25: =K25/2 -> 30.5 | M25: =J25+L25 -> 35.5
A26: Paolo | B26: Imbriani | C26: imbriani.paolo@hotmail.com | F26: ='lab test 1 - lab test 1 (5%)'!I25 -> 100 | G26: ='lab test 2 - lab test 2 (5 %)'!H24 -> 0 | H26: ='Programming Assignment 40% - Pr'!AH26 -> 0 | I26: =F26*0.1+G26*0.1+H26*0.8 -> 10 | J26: =I26/2 -> 5 | K26: 55 | L26: =K26/2 -> 27.5 | M26: =J26+L26 -> 32.5
A27: Daniel | B27: Keane | C27: 20098745@mail.wit.ie | F27: ='lab test 1 - lab test 1 (5%)'!I26 -> 53.428571 | G27: ='lab test 2 - lab test 2 (5 %)'!H25 -> 0 | H27: ='Programming Assignment 40% - Pr'!AH27 -> 0 | I27: =F27*0.1+G27*0.1+H27*0.8+K32 -> 41.842857 | J27: =I27/2 -> 20.921429 | K27: 49 | L27: =K27/2 -> 24.5 | M27: =J27+L27 -> 45.421429
A28: Andrew | B28: Koval | C28: 20098730@mail.wit.ie | F28: ='lab test 1 - lab test 1 (5%)'!I27 -> 75.714286 | G28: ='lab test 2 - lab test 2 (5 %)'!H26 -> 0 | H28: ='Programming Assignment 40% - Pr'!AH28 -> 0 | I28: =F28*0.1+G28*0.1+H28*0.8 -> 7.5714286 | J28: =I28/2 -> 3.7857143 | K28: 29.5 | L28: =K28/2 -> 14.75 | M28: =J28+L28 -> 18.535714 | N28: ?
A29: Jay | B29: Langford | C29: 20098918@mail.wit.ie | F29: ='lab test 1 - lab test 1 (5%)'!I28 -> 96 | G29: ='lab test 2 - lab test 2 (5 %)'!H27 -> 0 | H29: ='Programming Assignment 40% - Pr'!AH29 -> 0 | I29: =F29*0.1+G29*0.1+H29*0.8 -> 9.6 | J29: =I29/2 -> 4.8 | K29: 17 | L29: =K29/2 -> 8.5 | M29: =J29+L29 -> 13.3 | N29: Repeat Programming Assignment and FP
A30: Daniel | B30: Lawton | C30: 20084608@mail.wit.ie | F30: ='lab test 1 - lab test 1 (5%)'!I29 -> 92 | G30: ='lab test 2 - lab test 2 (5 %)'!H28 -> 0 | H30: ='Programming Assignment 40% - Pr'!AH30 -> 0 | I30: =F30*0.1+G30*0.1+H30*0.8 -> 9.2 | J30: =I30/2 -> 4.6 | L30: =K30/2 -> 0 | M30: =J30+L30 -> 4.6 | N30: Repeat CA and FP
A31: Denis | B31: Marincas | C31: 20099160@mail.wit.ie | F31: ='lab test 1 - lab test 1 (5%)'!I30 -> 86.714286 | G31: ='lab test 2 - lab test 2 (5 %)'!H29 -> 0 | H31: ='Programming Assignment 40% - Pr'!AH31 -> 0 | I31: =F31*0.1+G31*0.1+H31*0.8 -> 8.6714286 | J31: =I31/2 -> 4.3357143 | K31: 48 | L31: =K31/2 -> 24 | M31: =J31+L31 -> 28.335714
A32: Brendan | B32: Mayer | C32: 20097866@mail.wit.ie | F32: ='lab test 1 - lab test 1 (5%)'!I31 -> 100 | G32: ='lab test 2 - lab test 2 (5 %)'!H30 -> 0 | H32: ='Programming Assignment 40% - Pr'!AH32 -> 0 | I32: =F32*0.1+G32*0.1+H32*0.8 -> 10 | J32: =I32/2 -> 5 | K32: 36.5 | L32: =K32/2 -> 18.25 | M32: =J32+L32 -> 23.25
A33: Adam | B33: Mc Namara | C33: 20092433@mail.wit.ie | F33: ='lab test 1 - lab test 1 (5%)'!I32 -> 85.714286 | G33: ='lab test 2 - lab test 2 (5 %)'!H31 -> 0 | H33: ='Programming Assignment 40% - Pr'!AH33 -> 0 | I33: =F33*0.1+G33*0.1+H33*0.8 -> 8.5714286 | J33: =I33/2 -> 4.2857143 | L33: =K33/2 -> 0 | M33: =J33+L33 -> 4.2857143 | N33: Repeat CA and FP
A34: Sean | B34: Mercier | C34: 20094677@mail.wit.ie | F34: ='lab test 1 - lab test 1 (5%)'!I33 -> 100 | G34: ='lab test 2 - lab test 2 (5 %)'!H33 -> 0 | H34: ='Programming Assignment 40% - Pr'!AH35 -> 0 | I34: =F34*0.1+G34*0.1+H34*0.8 -> 10 | J34: =I34/2 -> 5 | K34: 60 | L34: =K34/2 -> 30 | M34: =J34+L34 -> 35
A35: Denis | B35: Miculescu | C35: 20098078@mail.wit.ie | F35: ='lab test 1 - lab test 1 (5%)'!I34 -> 100 | G35: ='lab test 2 - lab test 2 (5 %)'!H34 -> 0 | H35: ='Programming Assignment 40% - Pr'!AH36 -> 0 | I35: =F35*0.1+G35*0.1+H35*0.8 -> 10 | J35: =I35/2 -> 5 | K35: 35.5 | L35: =K35/2 -> 17.75 | M35: =J35+L35 -> 22.75
A36: Mustafe | B36: Mohamoud | C36: 20088394@mail.wit.ie | F36: ='lab test 1 - lab test 1 (5%)'!I35 -> 0 | G36: ='lab test 2 - lab test 2 (5 %)'!H35 -> 0 | H36: ='Programming Assignment 40% - Pr'!AH37 -> 0 | I36: =F36*0.1+G36*0.1+H36*0.8 -> 0 | J36: =I36/2 -> 0 | K36: 53.5 | L36: =K36/2 -> 26.75 | M36: =J36+L36 -> 26.75
A37: Barry | B37: Nolan | C37: 20098637@mail.wit.ie | F37: ='lab test 1 - lab test 1 (5%)'!I36 -> 86.714286 | G37: ='lab test 2 - lab test 2 (5 %)'!H36 -> 0 | H37: ='Programming Assignment 40% - Pr'!AH38 -> 0 | I37: =F37*0.1+G37*0.1+H37*0.8 -> 8.6714286 | J37: =I37/2 -> 4.3357143 | K37: 44 | L37: =K37/2 -> 22 | M37: =J37+L37 -> 26.335714
A38: Jay | B38: O Connor | C38: 20098583@mail.wit.ie | F38: ='lab test 1 - lab test 1 (5%)'!I37 -> 0 | G38: ='lab test 2 - lab test 2 (5 %)'!H37 -> 0 | H38: ='Programming Assignment 40% - Pr'!AH39 -> 0 | I38: =F38*0.1+G38*0.1+H38*0.8 -> 0 | J38: =I38/2 -> 0 | L38: =K38/2 -> 0 | M38: =J38+L38 -> 0 | N38: Repeat Programming Assignment and FP
A39: Anthony | B39: Power | C39: 20098384@mail.wit.ie | F39: ='lab test 1 - lab test 1 (5%)'!I38 -> 88 | G39: ='lab test 2 - lab test 2 (5 %)'!H38 -> 0 | H39: ='Programming Assignment 40% - Pr'!AH40 -> 0 | I39: =F39*0.1+G39*0.1+H39*0.8 -> 8.8 | J39: =I39/2 -> 4.4 | K39: 50 | L39: =K39/2 -> 25 | M39: =J39+L39 -> 29.4
A40: Mark | B40: Ryan | C40: 20098241@mail.wit.ie | F40: ='lab test 1 - lab test 1 (5%)'!I39 -> 45 | G40: ='lab test 2 - lab test 2 (5 %)'!H39 -> 0 | H40: ='Programming Assignment 40% - Pr'!AH41 -> 0 | I40: =F40*0.1+G40*0.1+H40*0.8 -> 4.5 | J40: =I40/2 -> 2.25 | K40: 40 | L40: =K40/2 -> 20 | M40: =J40+L40 -> 22.25
A41: Dean | B41: Sinnott | C41: 20067691@mail.wit.ie | F41: ='lab test 1 - lab test 1 (5%)'!I40 -> 91 | G41: ='lab test 2 - lab test 2 (5 %)'!H40 -> 0 | H41: ='Programming Assignment 40% - Pr'!AH42 -> 0 | I41: =F41*0.1+G41*0.1+H41*0.8 -> 9.1 | J41: =I41/2 -> 4.55 | K41: 46 | L41: =K41/2 -> 23 | M41: =J41+L41 -> 27.55
A42: Adrian | B42: Strymer | C42: 20097873@mail.wit.ie | F42: ='lab test 1 - lab test 1 (5%)'!I41 -> 100 | G42: ='lab test 2 - lab test 2 (5 %)'!H41 -> 0 | H42: ='Programming Assignment 40% - Pr'!AH43 -> 0 | I42: =F42*0.1+G42*0.1+H42*0.8 -> 10 | J42: =I42/2 -> 5 | K42: 35.5 | L42: =K42/2 -> 17.75 | M42: =J42+L42 -> 22.75
A43: Sam | B43: Taylor | F43: ='lab test 1 - lab test 1 (5%)'!I42 -> 79.428571
A44: Evan | B44: Tynan Geary | F44: ='lab test 1 - lab test 1 (5%)'!I43 -> 100
...

Sheet lab test 1 - lab test 1 (5%)
A1: lab test 1 (5%)
C2: Section C- Fixing Errors File | E2: Section A - Precedence - 30 Marks | G2: Sec B - Types - 30 Marks | I2: Total
C3: Number correct out of 10 | D3: Out of 40 | E3: Out of 6 | F3: Out of 30 | G3: How many correct out of 7 | H3: Out of 30 | I3: 0
C4: 10 | D4: =C4*4 -> 40 | E4: 6 | F4: =E4*30/6 -> 30 | G4: 7 | H4: =((G4/7)*30) -> 30 | I4: =SUM(D4,H4,F4) -> 100
A5: FirstName | B5: SurName | I5: =SUM(D5,H5,F5) -> 0
F6: =E6*30/7 -> 0 | H6: =G6*30/7 -> 0 | I6: =SUM(D6,H6,F6) -> 0
A7: Dawid | B7: Beres | C7: 10 | D7: =C7*4 -> 40 | E7: 6 | F7: =E7*30/6 -> 30 | G7: 7 | H7: =G7*30/7 -> 30 | I7: =SUM(D7,H7,F7) -> 100
A8: Jan | B8: Biernacki | C8: 10 | D8: =C8*4 -> 40 | E8: 6 | F8: =E8*30/6 -> 30 | G8: 7 | H8: =G8*30/7 -> 30 | I8: =SUM(D8,H8,F8) -> 100
A9: Arthur | B9: Bilyk | C9: 9 | D9: =C9*4 -> 36 | E9: 5 | F9: =E9*30/6 -> 25 | G9: 7 | H9: =G9*30/7 -> 30 | I9: =SUM(D9,H9,F9) -> 91
A10: Adam | B10: Cahill | C10: 8 | D10: =C10*4 -> 32 | E10: 6 | F10: =E10*30/6 -> 30 | G10: 7 | H10: =G10*30/7 -> 30 | I10: =SUM(D10,H10,F10) -> 92
A11: Dylan | B11: Chai | C11: 10 | D11: =C11*4 -> 40 | E11: 6 | F11: =E11*30/6 -> 30 | G11: 6 | H11: =G11*30/7 -> 25.714286 | I11: =SUM(D11,H11,F11) -> 95.714286
A12: Rendijs | B12: Cielava | C12: 10 | D12: =C12*4 -> 40 | E12: 6 | F12: =E12*30/6 -> 30 | G12: 7 | H12: =G12*30/7 -> 30 | I12: =SUM(D12,H12,F12) -> 100
A13: Liam | B13: Doocey | C13: 8 | D13: =C13*4 -> 32 | E13: 4 | F13: =E13*30/6 -> 20 | G13: 6 | H13: =G13*30/7 -> 25.714286 | I13: =SUM(D13,H13,F13) -> 77.714286
A14: Dean | B14: Doyle | D14: =C14*4 -> 0 | F14: =E14*30/6 -> 0 | H14: =G14*30/7 -> 0 | I14: =SUM(D14,H14,F14) -> 0
A15: Alex | B15: Fan | C15: 10 | D15: =C15*4 -> 40 | E15: 6 | F15: =E15*30/6 -> 30 | G15: 7 | H15: =G15*30/7 -> 30 | I15: =SUM(D15,H15,F15) -> 100
A16: Thomas | B16: Farrell | C16: 2 | D16: =C16*4 -> 8 | E16: 6 | F16: =E16*30/6 -> 30 | G16: 7 | H16: =G16*30/7 -> 30 | I16: =SUM(D16,H16,F16) -> 68
A17: Jordan | B17: Flynn | C17: 0 | D17: =C17*4 -> 0 | E17: 6 | F17: =E17*30/6 -> 30 | G17: 7 | H17: =G17*30/7 -> 30 | I17: =SUM(D17,H17,F17) -> 60 | J17: Did not make any changes to class_test_fixing_errors_file2
A18: Liam | B18: Flynn | C18: 10 | D18: =C18*4 -> 40 | E18: 6 | F18: =E18*30/6 -> 30 | G18: 7 | H18: =G18*30/7 -> 30 | I18: =SUM(D18,H18,F18) -> 100
A19: Kyla | B19: Franks | C19: 10 | D19: =C19*4 -> 40 | E19: 6 | F19: =E19*30/6 -> 30 | G19: 7 | H19: =G19*30/7 -> 30 | I19: =SUM(D19,H19,F19) -> 100
A20: Gjorgi | B20: Gjorgiev | C20: 10 | D20: =C20*4 -> 40 | E20: 5 | F20: =E20*30/6 -> 25 | G20: 7 | H20: =G20*30/7 -> 30 | I20: =SUM(D20,H20,F20) -> 95
A21: Killian | B21: Golds | D21: =C21*4 -> 0 | F21: =E21*30/6 -> 0 | H21: =G21*30/7 -> 0 | I21: =SUM(D21,H21,F21) -> 0
A22: Evan | B22: Hearne | C22: 9 | D22: =C22*4 -> 36 | E22: 6 | F22: =E22*30/6 -> 30 | G22: 7 | H22: =G22*30/7 -> 30 | I22: =SUM(D22,H22,F22) -> 96
A23: Ciaran | B23: Hickey | C23: 8 | D23: =C23*4 -> 32 | E23: 6 | F23: =E23*30/6 -> 30 | G23: 6 | H23: =G23*30/7 -> 25.714286 | I23: =SUM(D23,H23,F23) -> 87.714286
A24: Mark | B24: Hogan | C24: 10 | D24: =C24*4 -> 40 | E24: 6 | F24: =E24*30/6 -> 30 | G24: 7 | H24: =G24*30/7 -> 30 | I24: =SUM(D24,H24,F24) -> 100
A25: Paolo | B25: Imbriani | C25: 10 | D25: =C25*4 -> 40 | E25: 6 | F25: =E25*30/6 -> 30 | G25: 7 | H25: =G25*30/7 -> 30 | I25: =SUM(D25,H25,F25) -> 100
A26: Daniel | B26: Keane | C26: 3 | D26: =C26*4 -> 12 | E26: 4 | F26: =E26*30/6 -> 20 | G26: 5 | H26: =G26*30/7 -> 21.428571 | I26: =SUM(D26,H26,F26) -> 53.428571
A27: Andrew | B27: Koval | C27: 5 | D27: =C27*4 -> 20 | E27: 6 | F27: =E27*30/6 -> 30 | G27: 6 | H27: =G27*30/7 -> 25.714286 | I27: =SUM(D27,H27,F27) -> 75.714286
A28: Jay | B28: Langford | C28: 9 | D28: =C28*4 -> 36 | E28: 6 | F28: =E28*30/6 -> 30 | G28: 7 | H28: =G28*30/7 -> 30 | I28: =SUM(D28,H28,F28) -> 96
A29: Daniel | B29: Lawton | C29: 8 | D29: =C29*4 -> 32 | E29: 6 | F29: =E29*30/6 -> 30 | G29: 7 | H29: =G29*30/7 -> 30 | I29: =SUM(D29,H29,F29) -> 92
A30: Denis | B30: Marincas | C30: 9 | D30: =C30*4 -> 36 | E30: 5 | F30: =E30*30/6 -> 25 | G30: 6 | H30: =G30*30/7 -> 25.714286 | I30: =SUM(D30,H30,F30) -> 86.714286
A31: Brendan | B31: Mayer | C31: 10 | D31: =C31*4 -> 40 | E31: 6 | F31: =E31*30/6 -> 30 | G31: 7 | H31: =G31*30/7 -> 30 | I31: =SUM(D31,H31,F31) -> 100
A32: Adam | B32: Mc Namara | C32: 10 | D32: =C32*4 -> 40 | E32: 4 | F32: =E32*30/6 -> 20 | G32: 6 | H32: =G32*30/7 -> 25.714286 | I32: =SUM(D32,H32,F32) -> 85.714286
A33: Sean | B33: Mercier | C33: 10 | D33: =C33*4 -> 40 | E33: 6 | F33: =E33*30/6 -> 30 | G33: 7 | H33: =G33*30/7 -> 30 | I33: =SUM(D33,H33,F33) -> 100
A34: Denis | B34: Miculescu | C34: 10 | D34: =C34*4 -> 40 | E34: 6 | F34: =E34*30/6 -> 30 | G34: 7 | H34: =G34*30/7 -> 30 | I34: =SUM(D34,H34,F34) -> 100
A35: Mustafe | B35: Mohamoud | D35: =C35*4 -> 0 | F35: =E35*30/6 -> 0 | H35: =G35*30/7 -> 0 | I35: =SUM(D35,H35,F35) -> 0
A36: Barry | B36: Nolan | C36: 9 | D36: =C36*4 -> 36 | E36: 5 | F36: =E36*30/6 -> 25 | G36: 6 | H36: =G36*30/7 -> 25.714286 | I36: =SUM(D36,H36,F36) -> 86.714286 | K36: =J36/2 -> 0 | L36: =I36+K36 -> 86.714286
A37: Jay | B37: O Connor | D37: =C37*4 -> 0 | F37: =E37*30/6 -> 0 | H37: =G37*30/7 -> 0 | I37: =SUM(D37,H37,F37) -> 0
A38: Anthony | B38: Power | C38: 7 | D38: =C38*4 -> 28 | E38: 6 | F38: =E38*30/6 -> 30 | G38: 7 | H38: =G38*30/7 -> 30 | I38: =SUM(D38,H38,F38) -> 88
A39: Mark | B39: Ryan | C39: 0 | D39: =C39*4 -> 0 | E39: 3 | F39: =E39*30/6 -> 15 | G39: 7 | H39: =G39*30/7 -> 30 | I39: =SUM(D39,H39,F39) -> 45 | J39: Did not make any changes to class_test_fixing_errors_file2
A40: Dean | B40: Sinnott | C40: 9 | D40: =C40*4 -> 36 | E40: 5 | F40: =E40*30/6 -> 25 | G40: 7 | H40: =G40*30/7 -> 30 | I40: =SUM(D40,H40,F40) -> 91
...

Sheet lab test 2 - lab test 2 (5 %)
A1: lab test 2 (5 %)
F3: Stack Structure
C4: Working Program | D4: Anagram | E4: UpperCase | F4: Src and app used appropriately | G4: Properties.yaml changed appropriately (e.g. dependencies only in | H4: Total | I4: Comment
A5: FirstName | B5: SurName
H6: =SUM(C6:F6) -> 0
A7: Dawid | B7: Beres | C7: 2 | H7: =SUM(C7:F7) -> 2
A8: Jan | B8: Biernacki | H8: 80
A9: Arthur | B9: Bilyk | H9: =SUM(C9:F9) -> 0
A10: Adam | B10: Cahill | H10: =SUM(C10:F10) -> 0
A11: Dylan | B11: Chai | H11: =SUM(C11:F11) -> 0
A12: Rendijs | B12: Cielava | H12: =SUM(C12:F12) -> 0
A13: Liam | B13: Doocey | H13: =SUM(C13:F13) -> 0
A14: Dean | B14: Doyle | H14: =SUM(C14:F14) -> 0
A15: Alex | B15: Fan | H15: 80
A16: Thomas | B16: Farrell | H16: =SUM(C16:F16) -> 0
A17: Jordan | B17: Flynn | H17: =SUM(C17:F17) -> 0
A18: Liam | B18: Flynn | H18: =SUM(C18:F18) -> 0
A19: Kyla | B19: Franks | H19: =SUM(C19:F19) -> 0
A20: Gjorgi | B20: Gjorgiev | H20: =SUM(C20:F20) -> 0
A21: Killian | B21: Golds | H21: =SUM(C21:F21) -> 0
A22: Evan | B22: Hearne | H22: =SUM(C22:F22) -> 0
A23: Ciaran | B23: Hickey | H23: =SUM(C23:F23) -> 0
A24: Mark | B24: Hogan | H24: =SUM(C24:F24) -> 0
A25: Paolo | B25: Imbriani | H25: =SUM(C25:F25) -> 0
A26: Daniel | B26: Keane | H26: =SUM(C26:F26) -> 0
A27: Andrew | B27: Koval | H27: =SUM(C27:F27) -> 0
... A42: Sam | B42: Taylor | H42: =SUM(C42:F42) -> 0

Sheet Phase 1 - Programming Assignmen
A1: Formative Assessment (0%)
C3: Comment
A5: FirstName | B5: SurName
D6: =1 -> 1
A7: Dawid | B7: Beres | D7: =D6+1+D$4 -> 2
A8: Jan | B8: Biernacki | D8: =D7+1+D$4 -> 3
A9: Arthur | B9: Bilyk | D9: =D8+1+D$4 -> 4
A10: Adam | B10: Cahill | D10: =D9+1+D$4 -> 5
A11: Dylan | B11: Chai | D11: =D10+1+D$4 -> 6
A12: Rendijs | B12: Cielava | D12: =D11+1+D$4 -> 7
A13: Liam | B13: Doocey | D13: =D12+1+D$4 -> 8
A14: Dean | B14: Doyle | D14: =D13+1+D$4 -> 9
A15: Alex | B15: Fan | D15: =D14+1+D$4 -> 10
A16: Thomas | B16: Farrell | D16: =D15+1+D$4 -> 11
A17: Jordan | B17: Flynn | D17: =D16+1+D$4 -> 12
A18: Liam | B18: Flynn | D18: =D17+1+D$4 -> 13
... A42: Sam | B42: Taylor | D42: =D41+1+D$4 -> 37
D43: =D42+1+D$4 -> 38

Sheet Programming Assignment 40% - Pr
A1: Programming Assignment 40%
C2: Appropriateness of data design (13%) | F2: Validations (38%) | S2: Generation of Documents (27%) | Y2: Programming Style (13%) | AC2: Documentation (6%)
C3: Entities | D3: Data Types | E3: Csv files | F3: Entity fields(including primary key) (18%) | L3: Foreign Keys (4%) | N3: Allocations (3%) | O3: Timetable(16%) | S3: Csv files / entities(12 %) | V3: Timetables (15%) | Y3: Stack structure | Z3: properties.yaml (dependencies tidied up - in library: and executables: as appropriate | AA3: Breakdown of functionality into cohesive functions and files | AB3: Elegance of code including Haskell idiom | AC3: GitHub Classroom commits and messages | AD3: Readme.md reflection on process | AE3: Extras (wow) | AF3: Total | AG3: Interview | AH3: Total | AI3: Comment
F4: Lecturer | G4: Course | H4: Rooms | I4: Groups | J4: Modules | K4: Programmes | L4: Groups | M4: Allocations | N4: Lecturer is allocated <= hours as per ‘Available hours) | O4: No clashes for Groups | P4: No clashes for Lecturers | Q4: No clashes for Rooms | R4: Module fully timetabled | S4: Report on csv files | T4: Report on allocation | U4: Report on timetable | V4: Timetable for Groups (students) | W4: Timetable for Lecturers | X4: Timetable for Rooms
C5: 5 | D5: 5 | E5: 3 | F5: 3 | G5: 3 | H5: 3 | I5: 3 | J5: 3 | K5: 3 | L5: 2 | M5: 2 | N5: 3 | O5: 4 | P5: 4 | Q5: 4 | R5: 4 | S5: 4 | T5: 4 | U5: 4 | V5: 5 | W5: 5 | X5: 5 | Y5: 2 | Z5: 2 | AA5: 3 | AB5: 6 | AC5: 2 | AD5: 4 | AE5: 10 | AF5: =MIN(100,SUM(C$5:AE$5)) -> 100 | AG5: 100 | AH5: =AF5*AG5/100 -> 100
A6: FirstName | B6: SurName | E6: =SUM(C$5:E$5) -> 13 | K6: =SUM(F$5:K$5) -> 18 | M6: =SUM(L$5:M$5) -> 4 | R6: =SUM(O$5:R$5) -> 16 | U6: =SUM(S5:U5) -> 12 | X6: =SUM(V$5:X$5) -> 15 | AB6: =SUM(Y5:AB5) -> 13 | AD6: =SUM(AC$5:AD$5) -> 6 | AF6: =MIN(100,SUM(C$5:AE$5)) -> 100 | AG6: 100 | AH6: =AF6*AG6/100 -> 100
AF7: =MIN(100,SUM(C7:AE7)) -> 0 | AH7: =AF7*AG7/100 -> 0
A8: Dawid | B8: Beres | AF8: =MIN(100,SUM(C8:AE8)) -> 0 | AH8: =AF8*AG8/100 -> 0
A9: Jan | B9: Biernacki | AF9: =MIN(100,SUM(C9:AE9)) -> 0 | AH9: =AF9*AG9/100 -> 0
A10: Arthur | B10: Bilyk | AF10: =MIN(100,SUM(C10:AE10)) -> 0 | AH10: =AF10*AG10/100 -> 0
A11: Adam | B11: Cahill | AF11: =MIN(100,SUM(C11:AE11)) -> 0 | AH11: =AF11*AG11/100 -> 0
A12: Dylan | B12: Chai | AF12: =MIN(100,SUM(C12:AE12)) -> 0 | AH12: =AF12*AG12/100 -> 0
A13: Rendijs | B13: Cielava | AF13: =MIN(100,SUM(C13:AE13)) -> 0 | AH13: =AF13*AG13/100 -> 0
A14: Liam | B14: Doocey | AF14: =MIN(100,SUM(C14:AE14)) -> 0 | AH14: =AF14*AG14/100 -> 0
A15: Dean | B15: Doyle | AF15: =MIN(100,SUM(C15:AE15)) -> 0 | AH15: =AF15*AG15/100 -> 0
A16: Alex | B16: Fan | AF16: =MIN(100,SUM(C16:AE16)) -> 0 | AH16: =AF16*AG16/100 -> 0
A17: Thomas | B17: Farrell | AF17: =MIN(100,SUM(C17:AE17)) -> 0 | AH17: =AF17*AG17/100 -> 0
A18: Jordan | B18: Flynn | AF18: =MIN(100,SUM(C18:AE18)) -> 0 | AH18: =AF18*AG18/100 -> 0
A19: Liam | B19: Flynn | AF19: =MIN(100,SUM(C19:AE19)) -> 0 | AH19: =AF19*AG19/100 -> 0
... A43: Sam | B43: Taylor | AF43: =MIN(100,SUM(C43:AE43)) -> 0 | AH43: =AF43*AG43/100 -> 0
